Workbook

Sheet Portada
A19: PORRA MUNDIAL 2026
A22: FIFA WORLD CUP 26 · USA · CANADÁ · MÉXICO
A25: Grupo Papinenes · Porra privada · Pronósticos, clasificación automática y apuestas especiales
A28: Jugadores: Álvaro · Papá · Diego

Sheet Instrucciones
A1: INSTRUCCIONES
A2: Guía paso a paso para usar la porra sin tocar fórmulas.
A3: 1 | B3: Empieza por tu pestaña
B4: Busca la pestaña con tu nombre. Ahí rellenas todo lo tuyo: goles de cada partido, clasificado en eliminatorias y apuestas especiales. Solo escribe en celdas amarillas. Las celdas azules son fórmulas y las grises son referencias de otras pestañas.
A6: 2 | B6: Pronósticos de partidos
B7: En fase de grupos rellena Mis goles local y Mis goles visit.; la columna Clasificado aparece con '-' y no se usa. En octavos, cuartos, semifinales y final, además de los goles a 90 minutos, elige Clasificado: Local o Visitante.
A9: 3 | B9: Apuestas especiales
B10: En la parte inferior de tu pestaña escribe tus apuestas especiales antes de que empiece el torneo. El resultado oficial de esas apuestas se rellena después en Resumen, dentro del bloque Apuestas especiales.
A12: 4 | B12: Resultados reales
B13: La persona que administre la porra usa Partidos. En grupos rellena Resultado local y Resultado visitante. En eliminatorias rellena también Clasificado, que es quien pasa la ronda aunque sea en prórroga o penaltis.
A15: 5 | B15: Qué mirar durante el torneo
B16: Resumen es el dashboard principal: líder, clasificación completa, últimos partidos, análisis por jugador y apuestas especiales. Pronosticos consolida lo que ha puesto cada jugador y es de solo lectura.
A18: 6 | B18: Configuración y hojas técnicas
B19: Puntuacion permite cambiar los puntos de cada regla. Helpers >> separa las hojas de trabajo. _Helpers contiene cálculos internos y no requiere input.
A22: Pestañas con input: tu nombre, Partidos, Resumen (solo resultados oficiales de apuestas especiales) y Puntuacion.
A23: Pestañas sin input: Pronosticos, Helpers >> y _Helpers. Regla visual: amarillo = input; azul = fórmula; gris = referencia.
A24: Requisitos: Microsoft Excel 2010 o superior (Windows/Mac). No usa macros.

Sheet Resumen
A1: RESUMEN — DASHBOARD
A2: Todo se calcula solo. Lo único editable aquí es, en amarillo, el resultado oficial de las apuestas especiales.
A4: Indicadores del torneo
A5: LÍDER | C5: PUNTOS DEL LÍDER | E5: PARTIDOS JUGADOS | G5: PARTIDOS PENDIENTES | I5: PROGRESO TORNEO | K5: MEDIA PTS/PARTIDO LÍDER | M5: JUGADORES
A6: =_Helpers!$A$7 | C6: =_Helpers!$B$7 | E6: =COUNTIF(Partidos!$H$4:$H$107,"Finalizado") | G6: =104-COUNTIF(Partidos!$H$4:$H$107,"Finalizado") | I6: =IF(COUNTIF(Partidos!$H$4:$H$107,"Finalizado")=0,0,COUNTIF(Partidos!$H$4:$H$107,"Finalizado")/104) | K6: =IF(COUNTIF(Partidos!$H$4:$H$107,"Finalizado")=0,"",ROUND(_Helpers!$B$7/COUNTIF(Partidos!$H$4:$H$107,"Finalizado"),2)) | M6: 3
A8: Clasificación general | K8: Últimos partidos jugados
A9: Pos. | B9: Jugador | C9: Puntos | D9: Exactos | E9: Parciales | F9: Fallos | G9: % aciertos | H9: Medalla | I9: vs Líder | K9: Fecha | L9: Local | M9: Visitante | N9: Resultado
A10: 1 | B10: =_Helpers!$A$7 | C10: =_Helpers!$B$7 | D10: =_Helpers!$C$7 | E10: =_Helpers!$D$7 | F10: =_Helpers!$E$7 | G10: =_Helpers!$F$7 | H10: =IF(A10=1,"ORO",IF(A10=2,"PLATA",IF(A10=3,"BRONCE",""))) | I10: =IF(A10=1,0,$C$10-C10) | K10: =_Helpers!$X$69 | L10: =_Helpers!$U$69 | M10: =_Helpers!$V$69 | N10: =_Helpers!$W$69
A11: 2 | B11: =_Helpers!$A$8 | C11: =_Helpers!$B$8 | D11: =_Helpers!$C$8 | E11: =_Helpers!$D$8 | F11: =_Helpers!$E$8 | G11: =_Helpers!$F$8 | H11: =IF(A11=1,"ORO",IF(A11=2,"PLATA",IF(A11=3,"BRONCE",""))) | I11: =IF(A11=1,0,$C$10-C11) | K11: =_Helpers!$X$70 | L11: =_Helpers!$U$70 | M11: =_Helpers!$V$70 | N11: =_Helpers!$W$70
A12: 3 | B12: =_Helpers!$A$9 | C12: =_Helpers!$B$9 | D12: =_Helpers!$C$9 | E12: =_Helpers!$D$9 | F12: =_Helpers!$E$9 | G12: =_Helpers!$F$9 | H12: =IF(A12=1,"ORO",IF(A12=2,"PLATA",IF(A12=3,"BRONCE",""))) | I12: =IF(A12=1,0,$C$10-C12) | K12: =_Helpers!$X$71 | L12: =_Helpers!$U$71 | M12: =_Helpers!$V$71 | N12: =_Helpers!$W$71
K13: =_Helpers!$X$72 | L13: =_Helpers!$U$72 | M13: =_Helpers!$V$72 | N13: =_Helpers!$W$72
K14: =_Helpers!$X$73 | L14: =_Helpers!$U$73 | M14: =_Helpers!$V$73 | N14: =_Helpers!$W$73
A22: Análisis por jugador
A23: Elige un jugador: | C23: Álvaro | D23: (escribe el nombre exacto de una pestaña)
A24: Métrica | B24: Valor
A25: Posición actual | B25: =IFERROR(MATCH($C$23,_Helpers!$A$7:$A$9,0),"")
A26: Puntos totales | B26: =IFERROR(INDEX(_Helpers!$E$2:$E$4,MATCH($C$23,_Helpers!$A$2:$A$4,0)),0)
A27: Puntos por partidos | B27: =IFERROR(INDEX(_Helpers!$B$2:$B$4,MATCH($C$23,_Helpers!$A$2:$A$4,0)),0)
A28: Bonus de rondas | B28: =IFERROR(INDEX(_Helpers!$C$2:$C$4,MATCH($C$23,_Helpers!$A$2:$A$4,0)),0)
A29: Puntos apuestas especiales | B29: =IFERROR(INDEX(_Helpers!$D$2:$D$4,MATCH($C$23,_Helpers!$A$2:$A$4,0)),0)
A30: Distancia al líder | B30: =IFERROR(_Helpers!$B$7-INDEX(_Helpers!$E$2:$E$4,MATCH($C$23,_Helpers!$A$2:$A$4,0)),0)
A32: Apuestas especiales · resultado oficial | F32: Puntos por apuestas especiales
A33: Categoría | B33: Resultado oficial | C33: Aciertos | D33: Estado | F33: Jugador | G33: Puntos | H33: Aciertos | I33: Peso
A34: Campeón del Mundial | C34: =IF($B34="",0,IF(Álvaro!$B$111=$B34,1,0)+IF(Papá!$B$111=$B34,1,0)+IF(Diego!$B$111=$B34,1,0)) | D34: =IF($B34="","Pendiente","Cargado") | F34: =_Helpers!$A$2 | G34: =_Helpers!$D$2 | H34: =IF(Puntuacion!$B$19=0,0,G34/Puntuacion!$B$19) | I34: =Puntuacion!$B$19
A35: Subcampeón | C35: =IF($B35="",0,IF(Álvaro!$B$112=$B35,1,0)+IF(Papá!$B$112=$B35,1,0)+IF(Diego!$B$112=$B35,1,0)) | D35: =IF($B35="","Pendiente","Cargado") | F35: =_Helpers!$A$3 | G35: =_Helpers!$D$3 | H35: =IF(Puntuacion!$B$19=0,0,G35/Puntuacion!$B$19) | I35: =Puntuacion!$B$19
A36: Tercer equipo | C36: =IF($B36="",0,IF(Álvaro!$B$113=$B36,1,0)+IF(Papá!$B$113=$B36,1,0)+IF(Diego!$B$113=$B36,1,0)) | D36: =IF($B36="","Pendiente","Cargado") | F36: =_Helpers!$A$4 | G36: =_Helpers!$D$4 | H36: =IF(Puntuacion!$B$19=0,0,G36/Puntuacion!$B$19) | I36: =Puntuacion!$B$19
A37: Balón de oro de la FIFA | C37: =IF($B37="",0,IF(Álvaro!$B$114=$B37,1,0)+IF(Papá!$B$114=$B37,1,0)+IF(Diego!$B$114=$B37,1,0)) | D37: =IF($B37="","Pendiente","Cargado")
A38: Premio de la FIFA al mejor jugador joven | C38: =IF($B38="",0,IF(Álvaro!$B$115=$B38,1,0)+IF(Papá!$B$115=$B38,1,0)+IF(Diego!$B$115=$B38,1,0)) | D38: =IF($B38="","Pendiente","Cargado")
A39: Guante de oro de la FIFA | C39: =IF($B39="",0,IF(Álvaro!$B$116=$B39,1,0)+IF(Papá!$B$116=$B39,1,0)+IF(Diego!$B$116=$B39,1,0)) | D39: =IF($B39="","Pendiente","Cargado")
A40: Bota de oro de la FIFA | C40: =IF($B40="",0,IF(Álvaro!$B$117=$B40,1,0)+IF(Papá!$B$117=$B40,1,0)+IF(Diego!$B$117=$B40,1,0)) | D40: =IF($B40="","Pendiente","Cargado")
A41: Máximo goleador España | C41: =IF($B41="",0,IF(Álvaro!$B$118=$B41,1,0)+IF(Papá!$B$118=$B41,1,0)+IF(Diego!$B$118=$B41,1,0)) | D41: =IF($B41="","Pendiente","Cargado")
A46: Visualizaciones

Sheet Partidos
A1: CALENDARIO DE PARTIDOS
A2: Rellena resultados reales en amarillo; Clasificado solo aplica en eliminatorias.
A3: Nº partido | B3: Fecha | C3: Hora | D3: Equipo local | E3: Equipo visitante | F3: Resultado local | G3: Resultado visitante | H3: Estado | I3: Jornada | J3: Fase | K3: Clasificado
A4: 1 | B4: 11/06/2026 | C4: 13:00 | D4: México | E4: Sudáfrica | F4: 2 | G4: 0 | H4: =IF(AND(ISNUMBER(F4),ISNUMBER(G4)),"Finalizado","Pendiente") | I4: 1 | J4: Grupos | K4: -
A5: 2 | B5: 11/06/2026 | C5: 20:00 | D5: República de Corea | E5: República Checa | F5: 2 | G5: 1 | H5: =IF(AND(ISNUMBER(F5),ISNUMBER(G5)),"Finalizado","Pendiente") | I5: 1 | J5: Grupos | K5: -
A6: 3 | B6: 12/06/2026 | C6: 15:00 | D6: Canadá | E6: Bosnia y Herzegovina | F6: 1 | G6: 1 | H6: =IF(AND(ISNUMBER(F6),ISNUMBER(G6)),"Finalizado","Pendiente") | I6: 2 | J6: Grupos | K6: -
A7: 4 | B7: 12/06/2026 | C7: 18:00 | D7: Estados Unidos | E7: Paraguay | F7: 4 | G7: 1 | H7: =IF(AND(ISNUMBER(F7),ISNUMBER(G7)),"Finalizado","Pendiente") | I7: 4 | J7: Grupos | K7: -
A8: 5 | B8: 13/06/2026 | C8: 12:00 | D8: Catar | E8: Suiza | F8: 1 | G8: 1 | H8: =IF(AND(ISNUMBER(F8),ISNUMBER(G8)),"Finalizado","Pendiente") | I8: 2 | J8: Grupos | K8: -
A9: 6 | B9: 13/06/2026 | C9: 18:00 | D9: Brasil | E9: Marruecos | F9: 1 | G9: 1 | H9: =IF(AND(ISNUMBER(F9),ISNUMBER(G9)),"Finalizado","Pendiente") | I9: 3 | J9: Grupos | K9: -
A10: 7 | B10: 13/06/2026 | C10: 21:00 | D10: Haití | E10: Escocia | F10: 0 | G10: 1 | H10: =IF(AND(ISNUMBER(F10),ISNUMBER(G10)),"Finalizado","Pendiente") | I10: 3 | J10: Grupos | K10: -
A11: 8 | B11: 13/06/2026 | C11: 21:00 | D11: Australia | E11: Turquía | F11: 2 | G11: 0 | H11: =IF(AND(ISNUMBER(F11),ISNUMBER(G11)),"Finalizado","Pendiente") | I11: 4 | J11: Grupos | K11: -
A12: 9 | B12: 14/06/2026 | C12: 12:00 | D12: Alemania | E12: Curazao | F12: 7 | G12: 1 | H12: =IF(AND(ISNUMBER(F12),ISNUMBER(G12)),"Finalizado","Pendiente") | I12: 5 | J12: Grupos | K12: -
A13: 10 | B13: 14/06/2026 | C13: 15:00 | D13: Países Bajos | E13: Japón | F13: 2 | G13: 2 | H13: =IF(AND(ISNUMBER(F13),ISNUMBER(G13)),"Finalizado","Pendiente") | I13: 6 | J13: Grupos | K13: -
A14: 11 | B14: 14/06/2026 | C14: 19:00 | D14: Costa de Marfil | E14: Ecuador | F14: 1 | G14: 0 | H14: =IF(AND(ISNUMBER(F14),ISNUMBER(G14)),"Finalizado","Pendiente") | I14: 5 | J14: Grupos | K14: -
A15: 12 | B15: 14/06/2026 | C15: 20:00 | D15: Suecia | E15: Túnez | F15: 5 | G15: 1 | H15: =IF(AND(ISNUMBER(F15),ISNUMBER(G15)),"Finalizado","Pendiente") | I15: 6 | J15: Grupos | K15: -
... A28: 25 | B28: 18/06/2026 | C28: 12:00 | D28: República Checa | E28: Sudáfrica | F28: 1 | G28: 1 | H28: =IF(AND(ISNUMBER(F28),ISNUMBER(G28)),"Finalizado","Pendiente") | I28: 1 | J28: Grupos | K28: -
A29: 26 | B29: 18/06/2026 | C29: 12:00 | D29: Suiza | E29: Bosnia y Herzegovina | H29: =IF(AND(ISNUMBER(F29),ISNUMBER(G29)),"Finalizado","Pendiente") | I29: 2 | J29: Grupos | K29: -
A30: 27 | B30: 18/06/2026 | C30: 15:00 | D30: Canadá | E30: Catar | H30: =IF(AND(ISNUMBER(F30),ISNUMBER(G30)),"Finalizado","Pendiente") | I30: 2 | J30: Grupos | K30: -
A31: 28 | B31: 18/06/2026 | C31: 19:00 | D31: México | E31: República de Corea | H31: =IF(AND(ISNUMBER(F31),ISNUMBER(G31)),"Finalizado","Pendiente") | I31: 1 | J31: Grupos | K31: -
A32: 29 | B32: 19/06/2026 | C32: 12:00 | D32: Estados Unidos | E32: Australia | H32: =IF(AND(ISNUMBER(F32),ISNUMBER(G32)),"Finalizado","Pendiente") | I32: 4 | J32: Grupos | K32: -
A33: 30 | B33: 19/06/2026 | C33: 18:00 | D33: Escocia | E33: Marruecos | H33: =IF(AND(ISNUMBER(F33),ISNUMBER(G33)),"Finalizado","Pendiente") | I33: 3 | J33: Grupos | K33: -
A34: 31 | B34: 19/06/2026 | C34: 21:00 | D34: Brasil | E34: Haití | H34: =IF(AND(ISNUMBER(F34),ISNUMBER(G34)),"Finalizado","Pendiente") | I34: 3 | J34: Grupos | K34: -
A35: 32 | B35: 19/06/2026 | C35: 20:00 | D35: Turquía | E35: Paraguay | H35: =IF(AND(ISNUMBER(F35),ISNUMBER(G35)),"Finalizado","Pendiente") | I35: 4 | J35: Grupos | K35: -
A36: 33 | B36: 20/06/2026 | C36: 12:00 | D36: Países Bajos | E36: Suecia | H36: =IF(AND(ISNUMBER(F36),ISNUMBER(G36)),"Finalizado","Pendiente") | I36: 6 | J36: Grupos | K36: -
A37: 34 | B37: 20/06/2026 | C37: 16:00 | D37: Alemania | E37: Costa de Marfil | H37: =IF(AND(ISNUMBER(F37),ISNUMBER(G37)),"Finalizado","Pendiente") | I37: 5 | J37: Grupos | K37: -
A38: 35 | B38: 20/06/2026 | C38: 19:00 | D38: Ecuador | E38: Curazao | H38: =IF(AND(ISNUMBER(F38),ISNUMBER(G38)),"Finalizado","Pendiente") | I38: 5 | J38: Grupos | K38: -
A39: 36 | B39: 20/06/2026 | C39: 22:00 | D39: Túnez | E39: Japón | H39: =IF(AND(ISNUMBER(F39),ISNUMBER(G39)),"Finalizado","Pendiente") | I39: 6 | J39: Grupos | K39: -
A40: 37 | B40: 21/06/2026 | C40: 12:00 | D40: España | E40: Arabia Saudí | H40: =IF(AND(ISNUMBER(F40),ISNUMBER(G40)),"Finalizado","Pendiente") | I40: 8 | J40: Grupos | K40: -
... A75: 72 | B75: 27/06/2026 | C75: 21:00 | D75: Jordania | E75: Argentina | H75: =IF(AND(ISNUMBER(F75),ISNUMBER(G75)),"Finalizado","Pendiente") | I75: 10 | J75: Grupos | K75: -
A76: 73 | B76: 28/06/2026 | C76: 12:00 | D76: Ganador 1A | E76: Ganador 2B | H76: =IF(AND(ISNUMBER(F76),ISNUMBER(G76)),"Finalizado","Pendiente") | I76: 13 | J76: Dieciseisavos
A77: 74 | B77: 29/06/2026 | C77: 16:30 | D77: Ganador 1C | E77: Ganador 2D | H77: =IF(AND(ISNUMBER(F77),ISNUMBER(G77)),"Finalizado","Pendiente") | I77: 13 | J77: Dieciseisavos
A78: 75 | B78: 29/06/2026 | C78: 19:00 | D78: Ganador 1E | E78: Ganador 2F | H78: =IF(AND(ISNUMBER(F78),ISNUMBER(G78)),"Finalizado","Pendiente") | I78: 13 | J78: Dieciseisavos
A79: 76 | B79: 29/06/2026 | C79: 12:00 | D79: Ganador 1G | E79: Ganador 2H | H79: =IF(AND(ISNUMBER(F79),ISNUMBER(G79)),"Finalizado","Pendiente") | I79: 13 | J79: Dieciseisavos
A80: 77 | B80: 30/06/2026 | C80: 17:00 | D80: Ganador 1I | E80: Ganador 2J | H80: =IF(AND(ISNUMBER(F80),ISNUMBER(G80)),"Finalizado","Pendiente") | I80: 13 | J80: Dieciseisavos
A81: 78 | B81: 30/06/2026 | C81: 12:00 | D81: Ganador 1K | E81: Ganador 2L | H81: =IF(AND(ISNUMBER(F81),ISNUMBER(G81)),"Finalizado","Pendiente") | I81: 13 | J81: Dieciseisavos
A82: 79 | B82: 30/06/2026 | C82: 19:00 | D82: Ganador 1B | E82: Ganador 2A | H82: =IF(AND(ISNUMBER(F82),ISNUMBER(G82)),"Finalizado","Pendiente") | I82: 13 | J82: Dieciseisavos
A83: 80 | B83: 01/07/2026 | C83: 12:00 | D83: Ganador 1D | E83: Ganador 2C | H83: =IF(AND(ISNUMBER(F83),ISNUMBER(G83)),"Finalizado","Pendiente") | I83: 13 | J83: Dieciseisavos
A84: 81 | B84: 01/07/2026 | C84: 17:00 | D84: Ganador 1F | E84: Ganador 2E | H84: =IF(AND(ISNUMBER(F84),ISNUMBER(G84)),"Finalizado","Pendiente") | I84: 13 | J84: Dieciseisavos
A85: 82 | B85: 01/07/2026 | C85: 13:00 | D85: Ganador 1H | E85: Ganador 2G | H85: =IF(AND(ISNUMBER(F85),ISNUMBER(G85)),"Finalizado","Pendiente") | I85: 13 | J85: Dieciseisavos
A86: 83 | B86: 02/07/2026 | C86: 19:00 | D86: Ganador 1J | E86: Ganador 2I | H86: =IF(AND(ISNUMBER(F86),ISNUMBER(G86)),"Finalizado","Pendiente") | I86: 13 | J86: Dieciseisavos
...

Sheet Pronosticos
A1: PRONÓSTICOS (consolidado)
A2: Vista automática de todos los pronósticos; no hace falta editar esta hoja.
A3: Partido | B3: Equipo local | C3: Equipo visitante | D3: Jugador | E3: Goles local | F3: Goles visitante | G3: Puntos | H3: Clasificado | I3: Fase | J3: Clasif OK
A4: 1 | B4: =IFERROR(INDEX(Partidos!$D$4:$D$107,MATCH($A4,Partidos!$A$4:$A$107,0)),"") | C4: =IFERROR(INDEX(Partidos!$E$4:$E$107,MATCH($A4,Partidos!$A$4:$A$107,0)),"") | D4: Álvaro | E4: =IFERROR(INDEX(Álvaro!F$4:F$107,MATCH($A4,Álvaro!$A$4:$A$107,0)),"") | F4: =IFERROR(INDEX(Álvaro!G$4:G$107,MATCH($A4,Álvaro!$A$4:$A$107,0)),"") | G4: =IFERROR(IF(INDEX(Partidos!$H$4:$H$107,MATCH($A4,Partidos!$A$4:$A$107,0))<>"Finalizado","",IF(OR(NOT(ISNUMBER($E4)),NOT(ISNUMBER($F4))),"",IF(INDEX(Partidos!$J$4:$J$107,MATCH($A4,Partidos!$A$4:$A$107,0))="Grupos",IF(AND($E4=INDEX(Partidos!$F$4:$F$107,MATCH($A4,Partidos!$A$4:$A$107,0)),$F4=INDEX(Partidos!$G$4:$G$107,MATCH($A4,Partidos!$A$4:$A$107,0))),Puntuacion!$B$4,IF(($E4-$F4)=(INDEX(Partidos!$F$4:$F$107,MATCH($A4,Partidos!$A$4:$A$107,0))-INDEX(Partidos!$G$4:$G$107,MATCH($A4,Partidos!$A$4:$A$107,0))),Puntuacion!$B$5,IF(OR(AND($E4>$F4,INDEX(Partidos!$F$4:$F$107,MATCH($A4,Partidos!$A$4:$A$107,0))>INDEX(Partidos!$G$4:$G$107,MATCH($A4,Partidos!$A$4:$A$107,0))),AND($E4=$F4,INDEX(Partidos!$F$4:$F$107,MATCH($A4,Partidos!$A$4:$A$107,0))=INDEX(Partidos!$G$4:$G$107,MATCH($A4,Partidos!$A$4:$A$107,0))),AND($E4<$F4,INDEX(Partidos!$F$4:$F$107,MATCH($A4,Partidos!$A$4:$A$107,0))<INDEX(Partidos!$G$4:$G$107,MATCH($A4,Partidos!$A$4:$A$107,0)))),Puntuacion!$B$6,0))),IF(AND($E4=INDEX(Partidos!$F$4:$F$107,MATCH($A4,Partidos!$A$4:$A$107,0)),$F4=INDEX(Partidos!$G$4:$G$107,MATCH($A4,Partidos!$A$4:$A$107,0))),Puntuacion!$B$9,IF(($E4-$F4)=(INDEX(Partidos!$F$4:$F$107,MATCH($A4,Partidos!$A$4:$A$107,0))-INDEX(Partidos!$G$4:$G$107,MATCH($A4,Partidos!$A$4:$A$107,0))),Puntuacion!$B$10,IF(AND($H4<>"",$H4=INDEX(Partidos!$K$4:$K$107,MATCH($A4,Partidos!$A$4:$A$107,0))),Puntuacion!$B$11,0)))))),"") | H4: =IFERROR(INDEX(Álvaro!H$4:H$107,MATCH($A4,Álvaro!$A$4:$A$107,0)),"") | I4: =IFERROR(INDEX(Partidos!$J$4:$J$107,MATCH($A4,Partidos!$A$4:$A$107,0)),"") | J4: =IF(AND(INDEX(Partidos!$J$4:$J$107,MATCH($A4,Partidos!$A$4:$A$107,0))<>"Grupos",INDEX(Partidos!$H$4:$H$107,MATCH($A4,Partidos!$A$4:$A$107,0))="Finalizado",$H4<>"",$H4=INDEX(Partidos!$K$4:$K$107,MATCH($A4,Partidos!$A$4:$A$107,0))),1,0)
A5: 1 | B5: =IFERROR(INDEX(Partidos!$D$4:$D$107,MATCH($A5,Partidos!$A$4:$A$107,0)),"") | C5: =IFERROR(INDEX(Partidos!$E$4:$E$107,MATCH($A5,Partidos!$A$4:$A$107,0)),"") | D5: Papá | E5: =IFERROR(INDEX(Papá!F$4:F$107,MATCH($A5,Papá!$A$4:$A$107,0)),"") | F5: =IFERROR(INDEX(Papá!G$4:G$107,MATCH($A5,Papá!$A$4:$A$107,0)),"") | G5: =IFERROR(IF(INDEX(Partidos!$H$4:$H$107,MATCH($A5,Partidos!$A$4:$A$107,0))<>"Finalizado","",IF(OR(NOT(ISNUMBER($E5)),NOT(ISNUMBER($F5))),"",IF(INDEX(Partidos!$J$4:$J$107,MATCH($A5,Partidos!$A$4:$A$107,0))="Grupos",IF(AND($E5=INDEX(Partidos!$F$4:$F$107,MATCH($A5,Partidos!$A$4:$A$107,0)),$F5=INDEX(Partidos!$G$4:$G$107,MATCH($A5,Partidos!$A$4:$A$107,0))),Puntuacion!$B$4,IF(($E5-$F5)=(INDEX(Partidos!$F$4:$F$107,MATCH($A5,Partidos!$A$4:$A$107,0))-INDEX(Partidos!$G$4:$G$107,MATCH($A5,Partidos!$A$4:$A$107,0))),Puntuacion!$B$5,IF(OR(AND($E5>$F5,INDEX(Partidos!$F$4:$F$107,MATCH($A5,Partidos!$A$4:$A$107,0))>INDEX(Partidos!$G$4:$G$107,MATCH($A5,Partidos!$A$4:$A$107,0))),AND($E5=$F5,INDEX(Partidos!$F$4:$F$107,MATCH($A5,Partidos!$A$4:$A$107,0))=INDEX(Partidos!$G$4:$G$107,MATCH($A5,Partidos!$A$4:$A$107,0))),AND($E5<$F5,INDEX(Partidos!$F$4:$F$107,MATCH($A5,Partidos!$A$4:$A$107,0))<INDEX(Partidos!$G$4:$G$107,MATCH($A5,Partidos!$A$4:$A$107,0)))),Puntuacion!$B$6,0))),IF(AND($E5=INDEX(Partidos!$F$4:$F$107,MATCH($A5,Partidos!$A$4:$A$107,0)),$F5=INDEX(Partidos!$G$4:$G$107,MATCH($A5,Partidos!$A$4:$A$107,0))),Puntuacion!$B$9,IF(($E5-$F5)=(INDEX(Partidos!$F$4:$F$107,MATCH($A5,Partidos!$A$4:$A$107,0))-INDEX(Partidos!$G$4:$G$107,MATCH($A5,Partidos!$A$4:$A$107,0))),Puntuacion!$B$10,IF(AND($H5<>"",$H5=INDEX(Partidos!$K$4:$K$107,MATCH($A5,Partidos!$A$4:$A$107,0))),Puntuacion!$B$11,0)))))),"") | H5: =IFERROR(INDEX(Papá!H$4:H$107,MATCH($A5,Papá!$A$4:$A$107,0)),"") | I5: =IFERROR(INDEX(Partidos!$J$4:$J$107,MATCH($A5,Partidos!$A$4:$A$107,0)),"") | J5: =IF(AND(INDEX(Partidos!$J$4:$J$107,MATCH($A5,Partidos!$A$4:$A$107,0))<>"Grupos",INDEX(Partidos!$H$4:$H$107,MATCH($A5,Partidos!$A$4:$A$107,0))="Finalizado",$H5<>"",$H5=INDEX(Partidos!$K$4:$K$107,MATCH($A5,Partidos!$A$4:$A$107,0))),1,0)
A6: 1 | B6: =IFERROR(INDEX(Partidos!$D$4:$D$107,MATCH($A6,Partidos!$A$4:$A$107,0)),"") | C6: =IFERROR(INDEX(Partidos!$E$4:$E$107,MATCH($A6,Partidos!$A$4:$A$107,0)),"") | D6: Diego | E6: =IFERROR(INDEX(Diego!F$4:F$107,MATCH($A6,Diego!$A$4:$A$107,0)),"") | F6: =IFERROR(INDEX(Diego!G$4:G$107,MATCH($A6,Diego!$A$4:$A$107,0)),"") | G6: =IFERROR(IF(INDEX(Partidos!$H$4:$H$107,MATCH($A6,Partidos!$A$4:$A$107,0))<>"Finalizado","",IF(OR(NOT(ISNUMBER($E6)),NOT(ISNUMBER($F6))),"",IF(INDEX(Partidos!$J$4:$J$107,MATCH($A6,Partidos!$A$4:$A$107,0))="Grupos",IF(AND($E6=INDEX(Partidos!$F$4:$F$107,MATCH($A6,Partidos!$A$4:$A$107,0)),$F6=INDEX(Partidos!$G$4:$G$107,MATCH($A6,Partidos!$A$4:$A$107,0))),Puntuacion!$B$4,IF(($E6-$F6)=(INDEX(Partidos!$F$4:$F$107,MATCH($A6,Partidos!$A$4:$A$107,0))-INDEX(Partidos!$G$4:$G$107,MATCH($A6,Partidos!$A$4:$A$107,0))),Puntuacion!$B$5,IF(OR(AND($E6>$F6,INDEX(Partidos!$F$4:$F$107,MATCH($A6,Partidos!$A$4:$A$107,0))>INDEX(Partidos!$G$4:$G$107,MATCH($A6,Partidos!$A$4:$A$107,0))),AND($E6=$F6,INDEX(Partidos!$F$4:$F$107,MATCH($A6,Partidos!$A$4:$A$107,0))=INDEX(Partidos!$G$4:$G$107,MATCH($A6,Partidos!$A$4:$A$107,0))),AND($E6<$F6,INDEX(Partidos!$F$4:$F$107,MATCH($A6,Partidos!$A$4:$A$107,0))<INDEX(Partidos!$G$4:$G$107,MATCH($A6,Partidos!$A$4:$A$107,0)))),Puntuacion!$B$6,0))),IF(AND($E6=INDEX(Partidos!$F$4:$F$107,MATCH($A6,Partidos!$A$4:$A$107,0)),$F6=INDEX(Partidos!$G$4:$G$107,MATCH($A6,Partidos!$A$4:$A$107,0))),Puntuacion!$B$9,IF(($E6-$F6)=(INDEX(Partidos!$F$4:$F$107,MATCH($A6,Partidos!$A$4:$A$107,0))-INDEX(Partidos!$G$4:$G$107,MATCH($A6,Partidos!$A$4:$A$107,0))),Puntuacion!$B$10,IF(AND($H6<>"",$H6=INDEX(Partidos!$K$4:$K$107,MATCH($A6,Partidos!$A$4:$A$107,0))),Puntuacion!$B$11,0)))))),"") | H6: =IFERROR(INDEX(Diego!H$4:H$107,MATCH($A6,Diego!$A$4:$A$107,0)),"") | I6: =IFERROR(INDEX(Partidos!$J$4:$J$107,MATCH($A6,Partidos!$A$4:$A$107,0)),"") | J6: =IF(AND(INDEX(Partidos!$J$4:$J$107,MATCH($A6,Partidos!$A$4:$A$107,0))<>"Grupos",INDEX(Partidos!$H$4:$H$107,MATCH($A6,Partidos!$A$4:$A$107,0))="Finalizado",$H6<>"",$H6=INDEX(Partidos!$K$4:$K$107,MATCH($A6,Partidos!$A$4:$A$107,0))),1,0)
A7: 2 | B7: =IFERROR(INDEX(Partidos!$D$4:$D$107,MATCH($A7,Partidos!$A$4:$A$107,0)),"") | C7: =IFERROR(INDEX(Partidos!$E$4:$E$107,MATCH($A7,Partidos!$A$4:$A$107,0)),"") | D7: Álvaro | E7: =IFERROR(INDEX(Álvaro!F$4:F$107,MATCH($A7,Álvaro!$A$4:$A$107,0)),"") | F7: =IFERROR(INDEX(Álvaro!G$4:G$107,MATCH($A7,Álvaro!$A$4:$A$107,0)),"") | G7: =IFERROR(IF(INDEX(Partidos!$H$4:$H$107,MATCH($A7,Partidos!$A$4:$A$107,0))<>"Finalizado","",IF(OR(NOT(ISNUMBER($E7)),NOT(ISNUMBER($F7))),"",IF(INDEX(Partidos!$J$4:$J$107,MATCH($A7,Partidos!$A$4:$A$107,0))="Grupos",IF(AND($E7=INDEX(Partidos!$F$4:$F$107,MATCH($A7,Partidos!$A$4:$A$107,0)),$F7=INDEX(Partidos!$G$4:$G$107,MATCH($A7,Partidos!$A$4:$A$107,0))),Puntuacion!$B$4,IF(($E7-$F7)=(INDEX(Partidos!$F$4:$F$107,MATCH($A7,Partidos!$A$4:$A$107,0))-INDEX(Partidos!$G$4:$G$107,MATCH($A7,Partidos!$A$4:$A$107,0))),Puntuacion!$B$5,IF(OR(AND($E7>$F7,INDEX(Partidos!$F$4:$F$107,MATCH($A7,Partidos!$A$4:$A$107,0))>INDEX(Partidos!$G$4:$G$107,MATCH($A7,Partidos!$A$4:$A$107,0))),AND($E7=$F7,INDEX(Partidos!$F$4:$F$107,MATCH($A7,Partidos!$A$4:$A$107,0))=INDEX(Partidos!$G$4:$G$107,MATCH($A7,Partidos!$A$4:$A$107,0))),AND($E7<$F7,INDEX(Partidos!$F$4:$F$107,MATCH($A7,Partidos!$A$4:$A$107,0))<INDEX(Partidos!$G$4:$G$107,MATCH($A7,Partidos!$A$4:$A$107,0)))),Puntuacion!$B$6,0))),IF(AND($E7=INDEX(Partidos!$F$4:$F$107,MATCH($A7,Partidos!$A$4:$A$107,0)),$F7=INDEX(Partidos!$G$4:$G$107,MATCH($A7,Partidos!$A$4:$A$107,0))),Puntuacion!$B$9,IF(($E7-$F7)=(INDEX(Partidos!$F$4:$F$107,MATCH($A7,Partidos!$A$4:$A$107,0))-INDEX(Partidos!$G$4:$G$107,MATCH($A7,Partidos!$A$4:$A$107,0))),Puntuacion!$B$10,IF(AND($H7<>"",$H7=INDEX(Partidos!$K$4:$K$107,MATCH($A7,Partidos!$A$4:$A$107,0))),Puntuacion!$B$11,0)))))),"") | H7: =IFERROR(INDEX(Álvaro!H$4:H$107,MATCH($A7,Álvaro!$A$4:$A$107,0)),"") | I7: =IFERROR(INDEX(Partidos!$J$4:$J$107,MATCH($A7,Partidos!$A$4:$A$107,0)),"") | J7: =IF(AND(INDEX(Partidos!$J$4:$J$107,MATCH($A7,Partidos!$A$4:$A$107,0))<>"Grupos",INDEX(Partidos!$H$4:$H$107,MATCH($A7,Partidos!$A$4:$A$107,0))="Finalizado",$H7<>"",$H7=INDEX(Partidos!$K$4:$K$107,MATCH($A7,Partidos!$A$4:$A$107,0))),1,0)
A8: 2 | B8: =IFERROR(INDEX(Partidos!$D$4:$D$107,MATCH($A8,Partidos!$A$4:$A$107,0)),"") | C8: =IFERROR(INDEX(Partidos!$E$4:$E$107,MATCH($A8,Partidos!$A$4:$A$107,0)),"") | D8: Papá | E8: =IFERROR(INDEX(Papá!F$4:F$107,MATCH($A8,Papá!$A$4:$A$107,0)),"") | F8: =IFERROR(INDEX(Papá!G$4:G$107,MATCH($A8,Papá!$A$4:$A$107,0)),"") | G8: =IFERROR(IF(INDEX(Partidos!$H$4:$H$107,MATCH($A8,Partidos!$A$4:$A$107,0))<>"Finalizado","",IF(OR(NOT(ISNUMBER($E8)),NOT(ISNUMBER($F8))),"",IF(INDEX(Partidos!$J$4:$J$107,MATCH($A8,Partidos!$A$4:$A$107,0))="Grupos",IF(AND($E8=INDEX(Partidos!$F$4:$F$107,MATCH($A8,Partidos!$A$4:$A$107,0)),$F8=INDEX(Partidos!$G$4:$G$107,MATCH($A8,Partidos!$A$4:$A$107,0))),Puntuacion!$B$4,IF(($E8-$F8)=(INDEX(Partidos!$F$4:$F$107,MATCH($A8,Partidos!$A$4:$A$107,0))-INDEX(Partidos!$G$4:$G$107,MATCH($A8,Partidos!$A$4:$A$107,0))),Puntuacion!$B$5,IF(OR(AND($E8>$F8,INDEX(Partidos!$F$4:$F$107,MATCH($A8,Partidos!$A$4:$A$107,0))>INDEX(Partidos!$G$4:$G$107,MATCH($A8,Partidos!$A$4:$A$107,0))),AND($E8=$F8,INDEX(Partidos!$F$4:$F$107,MATCH($A8,Partidos!$A$4:$A$107,0))=INDEX(Partidos!$G$4:$G$107,MATCH($A8,Partidos!$A$4:$A$107,0))),AND($E8<$F8,INDEX(Partidos!$F$4:$F$107,MATCH($A8,Partidos!$A$4:$A$107,0))<INDEX(Partidos!$G$4:$G$107,MATCH($A8,Partidos!$A$4:$A$107,0)))),Puntuacion!$B$6,0))),IF(AND($E8=INDEX(Partidos!$F$4:$F$107,MATCH($A8,Partidos!$A$4:$A$107,0)),$F8=INDEX(Partidos!$G$4:$G$107,MATCH($A8,Partidos!$A$4:$A$107,0))),Puntuacion!$B$9,IF(($E8-$F8)=(INDEX(Partidos!$F$4:$F$107,MATCH($A8,Partidos!$A$4:$A$107,0))-INDEX(Partidos!$G$4:$G$107,MATCH($A8,Partidos!$A$4:$A$107,0))),Puntuacion!$B$10,IF(AND($H8<>"",$H8=INDEX(Partidos!$K$4:$K$107,MATCH($A8,Partidos!$A$4:$A$107,0))),Puntuacion!$B$11,0)))))),"") | H8: =IFERROR(INDEX(Papá!H$4:H$107,MATCH($A8,Papá!$A$4:$A$107,0)),"") | I8: =IFERROR(INDEX(Partidos!$J$4:$J$107,MATCH($A8,Partidos!$A$4:$A$107,0)),"") | J8: =IF(AND(INDEX(Partidos!$J$4:$J$107,MATCH($A8,Partidos!$A$4:$A$107,0))<>"Grupos",INDEX(Partidos!$H$4:$H$107,MATCH($A8,Partidos!$A$4:$A$107,0))="Finalizado",$H8<>"",$H8=INDEX(Partidos!$K$4:$K$107,MATCH($A8,Partidos!$A$4:$A$107,0))),1,0)
A9: 2 | B9: =IFERROR(INDEX(Partidos!$D$4:$D$107,MATCH($A9,Partidos!$A$4:$A$107,0)),"") | C9: =IFERROR(INDEX(Partidos!$E$4:$E$107,MATCH($A9,Partidos!$A$4:$A$107,0)),"") | D9: Diego | E9: =IFERROR(INDEX(Diego!F$4:F$107,MATCH($A9,Diego!$A$4:$A$107,0)),"") | F9: =IFERROR(INDEX(Diego!G$4:G$107,MATCH($A9,Diego!$A$4:$A$107,0)),"") | G9: =IFERROR(IF(INDEX(Partidos!$H$4:$H$107,MATCH($A9,Partidos!$A$4:$A$107,0))<>"Finalizado","",IF(OR(NOT(ISNUMBER($E9)),NOT(ISNUMBER($F9))),"",IF(INDEX(Partidos!$J$4:$J$107,MATCH($A9,Partidos!$A$4:$A$107,0))="Grupos",IF(AND($E9=INDEX(Partidos!$F$4:$F$107,MATCH($A9,Partidos!$A$4:$A$107,0)),$F9=INDEX(Partidos!$G$4:$G$107,MATCH($A9,Partidos!$A$4:$A$107,0))),Puntuacion!$B$4,IF(($E9-$F9)=(INDEX(Partidos!$F$4:$F$107,MATCH($A9,Partidos!$A$4:$A$107,0))-INDEX(Partidos!$G$4:$G$107,MATCH($A9,Partidos!$A$4:$A$107,0))),Puntuacion!$B$5,IF(OR(AND($E9>$F9,INDEX(Partidos!$F$4:$F$107,MATCH($A9,Partidos!$A$4:$A$107,0))>INDEX(Partidos!$G$4:$G$107,MATCH($A9,Partidos!$A$4:$A$107,0))),AND($E9=$F9,INDEX(Partidos!$F$4:$F$107,MATCH($A9,Partidos!$A$4:$A$107,0))=INDEX(Partidos!$G$4:$G$107,MATCH($A9,Partidos!$A$4:$A$107,0))),AND($E9<$F9,INDEX(Partidos!$F$4:$F$107,MATCH($A9,Partidos!$A$4:$A$107,0))<INDEX(Partidos!$G$4:$G$107,MATCH($A9,Partidos!$A$4:$A$107,0)))),Puntuacion!$B$6,0))),IF(AND($E9=INDEX(Partidos!$F$4:$F$107,MATCH($A9,Partidos!$A$4:$A$107,0)),$F9=INDEX(Partidos!$G$4:$G$107,MATCH($A9,Partidos!$A$4:$A$107,0))),Puntuacion!$B$9,IF(($E9-$F9)=(INDEX(Partidos!$F$4:$F$107,MATCH($A9,Partidos!$A$4:$A$107,0))-INDEX(Partidos!$G$4:$G$107,MATCH($A9,Partidos!$A$4:$A$107,0))),Puntuacion!$B$10,IF(AND($H9<>"",$H9=INDEX(Partidos!$K$4:$K$107,MATCH($A9,Partidos!$A$4:$A$107,0))),Puntuacion!$B$11,0)))))),"") | H9: =IFERROR(INDEX(Diego!H$4:H$107,MATCH($A9,Diego!$A$4:$A$107,0)),"") | I9: =IFERROR(INDEX(Partidos!$J$4:$J$107,MATCH($A9,Partidos!$A$4:$A$107,0)),"") | J9: =IF(AND(INDEX(Partidos!$J$4:$J$107,MATCH($A9,Partidos!$A$4:$A$107,0))<>"Grupos",INDEX(Partidos!$H$4:$H$107,MATCH($A9,Partidos!$A$4:$A$107,0))="Finalizado",$H9<>"",$H9=INDEX(Partidos!$K$4:$K$107,MATCH($A9,Partidos!$A$4:$A$107,0))),1,0)
A10: 3 | B10: =IFERROR(INDEX(Partidos!$D$4:$D$107,MATCH($A10,Partidos!$A$4:$A$107,0)),"") | C10: =IFERROR(INDEX(Partidos!$E$4:$E$107,MATCH($A10,Partidos!$A$4:$A$107,0)),"") | D10: Álvaro | E10: =IFERROR(INDEX(Álvaro!F$4:F$107,MATCH($A10,Álvaro!$A$4:$A$107,0)),"") | F10: =IFERROR(INDEX(Álvaro!G$4:G$107,MATCH($A10,Álvaro!$A$4:$A$107,0)),"") | G10: =IFERROR(IF(INDEX(Partidos!$H$4:$H$107,MATCH($A10,Partidos!$A$4:$A$107,0))<>"Finalizado","",IF(OR(NOT(ISNUMBER($E10)),NOT(ISNUMBER($F10))),"",IF(INDEX(Partidos!$J$4:$J$107,MATCH($A10,Partidos!$A$4:$A$107,0))="Grupos",IF(AND($E10=INDEX(Partidos!$F$4:$F$107,MATCH($A10,Partidos!$A$4:$A$107,0)),$F10=INDEX(Partidos!$G$4:$G$107,MATCH($A10,Partidos!$A$4:$A$107,0))),Puntuacion!$B$4,IF(($E10-$F10)=(INDEX(Partidos!$F$4:$F$107,MATCH($A10,Partidos!$A$4:$A$107,0))-INDEX(Partidos!$G$4:$G$107,MATCH($A10,Partidos!$A$4:$A$107,0))),Puntuacion!$B$5,IF(OR(AND($E10>$F10,INDEX(Partidos!$F$4:$F$107,MATCH($A10,Partidos!$A$4:$A$107,0))>INDEX(Partidos!$G$4:$G$107,MATCH($A10,Partidos!$A$4:$A$107,0))),AND($E10=$F10,INDEX(Partidos!$F$4:$F$107,MATCH($A10,Partidos!$A$4:$A$107,0))=INDEX(Partidos!$G$4:$G$107,MATCH($A10,Partidos!$A$4:$A$107,0))),AND($E10<$F10,INDEX(Partidos!$F$4:$F$107,MATCH($A10,Partidos!$A$4:$A$107,0))<INDEX(Partidos!$G$4:$G$107,MATCH($A10,Partidos!$A$4:$A$107,0)))),Puntuacion!$B$6,0))),IF(AND($E10=INDEX(Partidos!$F$4:$F$107,MATCH($A10,Partidos!$A$4:$A$107,0)),$F10=INDEX(Partidos!$G$4:$G$107,MATCH($A10,Partidos!$A$4:$A$107,0))),Puntuacion!$B$9,IF(($E10-$F10)=(INDEX(Partidos!$F$4:$F$107,MATCH($A10,Partidos!$A$4:$A$107,0))-INDEX(Partidos!$G$4:$G$107,MATCH($A10,Partidos!$A$4:$A$107,0))),Puntuacion!$B$10,IF(AND($H10<>"",$H10=INDEX(Partidos!$K$4:$K$107,MATCH($A10,Partidos!$A$4:$A$107,0))),Puntuacion!$B$11,0)))))),"") | H10: =IFERROR(INDEX(Álvaro!H$4:H$107,MATCH($A10,Álvaro!$A$4:$A$107,0)),"") | I10: =IFERROR(INDEX(Partidos!$J$4:$J$107,MATCH($A10,Partidos!$A$4:$A$107,0)),"") | J10: =IF(AND(INDEX(Partidos!$J$4:$J$107,MATCH($A10,Partidos!$A$4:$A$107,0))<>"Grupos",INDEX(Partidos!$H$4:$H$107,MATCH($A10,Partidos!$A$4:$A$107,0))="Finalizado",$H10<>"",$H10=INDEX(Partidos!$K$4:$K$107,MATCH($A10,Partidos!$A$4:$A$107,0))),1,0)
A11: 3 | B11: =IFERROR(INDEX(Partidos!$D$4:$D$107,MATCH($A11,Partidos!$A$4:$A$107,0)),"") | C11: =IFERROR(INDEX(Partidos!$E$4:$E$107,MATCH($A11,Partidos!$A$4:$A$107,0)),"") | D11: Papá | E11: =IFERROR(INDEX(Papá!F$4:F$107,MATCH($A11,Papá!$A$4:$A$107,0)),"") | F11: =IFERROR(INDEX(Papá!G$4:G$107,MATCH($A11,Papá!$A$4:$A$107,0)),"") | G11: =IFERROR(IF(INDEX(Partidos!$H$4:$H$107,MATCH($A11,Partidos!$A$4:$A$107,0))<>"Finalizado","",IF(OR(NOT(ISNUMBER($E11)),NOT(ISNUMBER($F11))),"",IF(INDEX(Partidos!$J$4:$J$107,MATCH($A11,Partidos!$A$4:$A$107,0))="Grupos",IF(AND($E11=INDEX(Partidos!$F$4:$F$107,MATCH($A11,Partidos!$A$4:$A$107,0)),$F11=INDEX(Partidos!$G$4:$G$107,MATCH($A11,Partidos!$A$4:$A$107,0))),Puntuacion!$B$4,IF(($E11-$F11)=(INDEX(Partidos!$F$4:$F$107,MATCH($A11,Partidos!$A$4:$A$107,0))-INDEX(Partidos!$G$4:$G$107,MATCH($A11,Partidos!$A$4:$A$107,0))),Puntuacion!$B$5,IF(OR(AND($E11>$F11,INDEX(Partidos!$F$4:$F$107,MATCH($A11,Partidos!$A$4:$A$107,0))>INDEX(Partidos!$G$4:$G$107,MATCH($A11,Partidos!$A$4:$A$107,0))),AND($E11=$F11,INDEX(Partidos!$F$4:$F$107,MATCH($A11,Partidos!$A$4:$A$107,0))=INDEX(Partidos!$G$4:$G$107,MATCH($A11,Partidos!$A$4:$A$107,0))),AND($E11<$F11,INDEX(Partidos!$F$4:$F$107,MATCH($A11,Partidos!$A$4:$A$107,0))<INDEX(Partidos!$G$4:$G$107,MATCH($A11,Partidos!$A$4:$A$107,0)))),Puntuacion!$B$6,0))),IF(AND($E11=INDEX(Partidos!$F$4:$F$107,MATCH($A11,Partidos!$A$4:$A$107,0)),$F11=INDEX(Partidos!$G$4:$G$107,MATCH($A11,Partidos!$A$4:$A$107,0))),Puntuacion!$B$9,IF(($E11-$F11)=(INDEX(Partidos!$F$4:$F$107,MATCH($A11,Partidos!$A$4:$A$107,0))-INDEX(Partidos!$G$4:$G$107,MATCH($A11,Partidos!$A$4:$A$107,0))),Puntuacion!$B$10,IF(AND($H11<>"",$H11=INDEX(Partidos!$K$4:$K$107,MATCH($A11,Partidos!$A$4:$A$107,0))),Puntuacion!$B$11,0)))))),"") | H11: =IFERROR(INDEX(Papá!H$4:H$107,MATCH($A11,Papá!$A$4:$A$107,0)),"") | I11: =IFERROR(INDEX(Partidos!$J$4:$J$107,MATCH($A11,Partidos!$A$4:$A$107,0)),"") | J11: =IF(AND(INDEX(Partidos!$J$4:$J$107,MATCH($A11,Partidos!$A$4:$A$107,0))<>"Grupos",INDEX(Partidos!$H$4:$H$107,MATCH($A11,Partidos!$A$4:$A$107,0))="Finalizado",$H11<>"",$H11=INDEX(Partidos!$K$4:$K$107,MATCH($A11,Partidos!$A$4:$A$107,0))),1,0)
A12: 3 | B12: =IFERROR(INDEX(Partidos!$D$4:$D$107,MATCH($A12,Partidos!$A$4:$A$107,0)),"") | C12: =IFERROR(INDEX(Partidos!$E$4:$E$107,MATCH($A12,Partidos!$A$4:$A$107,0)),"") | D12: Diego | E12: =IFERROR(INDEX(Diego!F$4:F$107,MATCH($A12,Diego!$A$4:$A$107,0)),"") | F12: =IFERROR(INDEX(Diego!G$4:G$107,MATCH($A12,Diego!$A$4:$A$107,0)),"") | G12: =IFERROR(IF(INDEX(Partidos!$H$4:$H$107,MATCH($A12,Partidos!$A$4:$A$107,0))<>"Finalizado","",IF(OR(NOT(ISNUMBER($E12)),NOT(ISNUMBER($F12))),"",IF(INDEX(Partidos!$J$4:$J$107,MATCH($A12,Partidos!$A$4:$A$107,0))="Grupos",IF(AND($E12=INDEX(Partidos!$F$4:$F$107,MATCH($A12,Partidos!$A$4:$A$107,0)),$F12=INDEX(Partidos!$G$4:$G$107,MATCH($A12,Partidos!$A$4:$A$107,0))),Puntuacion!$B$4,IF(($E12-$F12)=(INDEX(Partidos!$F$4:$F$107,MATCH($A12,Partidos!$A$4:$A$107,0))-INDEX(Partidos!$G$4:$G$107,MATCH($A12,Partidos!$A$4:$A$107,0))),Puntuacion!$B$5,IF(OR(AND($E12>$F12,INDEX(Partidos!$F$4:$F$107,MATCH($A12,Partidos!$A$4:$A$107,0))>INDEX(Partidos!$G$4:$G$107,MATCH($A12,Partidos!$A$4:$A$107,0))),AND($E12=$F12,INDEX(Partidos!$F$4:$F$107,MATCH($A12,Partidos!$A$4:$A$107,0))=INDEX(Partidos!$G$4:$G$107,MATCH($A12,Partidos!$A$4:$A$107,0))),AND($E12<$F12,INDEX(Partidos!$F$4:$F$107,MATCH($A12,Partidos!$A$4:$A$107,0))<INDEX(Partidos!$G$4:$G$107,MATCH($A12,Partidos!$A$4:$A$107,0)))),Puntuacion!$B$6,0))),IF(AND($E12=INDEX(Partidos!$F$4:$F$107,MATCH($A12,Partidos!$A$4:$A$107,0)),$F12=INDEX(Partidos!$G$4:$G$107,MATCH($A12,Partidos!$A$4:$A$107,0))),Puntuacion!$B$9,IF(($E12-$F12)=(INDEX(Partidos!$F$4:$F$107,MATCH($A12,Partidos!$A$4:$A$107,0))-INDEX(Partidos!$G$4:$G$107,MATCH($A12,Partidos!$A$4:$A$107,0))),Puntuacion!$B$10,IF(AND($H12<>"",$H12=INDEX(Partidos!$K$4:$K$107,MATCH($A12,Partidos!$A$4:$A$107,0))),Puntuacion!$B$11,0)))))),"") | H12: =IFERROR(INDEX(Diego!H$4:H$107,MATCH($A12,Diego!$A$4:$A$107,0)),"") | I12: =IFERROR(INDEX(Partidos!$J$4:$J$107,MATCH($A12,Partidos!$A$4:$A$107,0)),"") | J12: =IF(AND(INDEX(Partidos!$J$4:$J$107,MATCH($A12,Partidos!$A$4:$A$107,0))<>"Grupos",INDEX(Partidos!$H$4:$H$107,MATCH($A12,Partidos!$A$4:$A$107,0))="Finalizado",$H12<>"",$H12=INDEX(Partidos!$K$4:$K$107,MATCH($A12,Partidos!$A$4:$A$107,0))),1,0)
A13: 4 | B13: =IFERROR(INDEX(Partidos!$D$4:$D$107,MATCH($A13,Partidos!$A$4:$A$107,0)),"") | C13: =IFERROR(INDEX(Partidos!$E$4:$E$107,MATCH($A13,Partidos!$A$4:$A$107,0)),"") | D13: Álvaro | E13: =IFERROR(INDEX(Álvaro!F$4:F$107,MATCH($A13,Álvaro!$A$4:$A$107,0)),"") | F13: =IFERROR(INDEX(Álvaro!G$4:G$107,MATCH($A13,Álvaro!$A$4:$A$107,0)),"") | G13: =IFERROR(IF(INDEX(Partidos!$H$4:$H$107,MATCH($A13,Partidos!$A$4:$A$107,0))<>"Finalizado","",IF(OR(NOT(ISNUMBER($E13)),NOT(ISNUMBER($F13))),"",IF(INDEX(Partidos!$J$4:$J$107,MATCH($A13,Partidos!$A$4:$A$107,0))="Grupos",IF(AND($E13=INDEX(Partidos!$F$4:$F$107,MATCH($A13,Partidos!$A$4:$A$107,0)),$F13=INDEX(Partidos!$G$4:$G$107,MATCH($A13,Partidos!$A$4:$A$107,0))),Puntuacion!$B$4,IF(($E13-$F13)=(INDEX(Partidos!$F$4:$F$107,MATCH($A13,Partidos!$A$4:$A$107,0))-INDEX(Partidos!$G$4:$G$107,MATCH($A13,Partidos!$A$4:$A$107,0))),Puntuacion!$B$5,IF(OR(AND($E13>$F13,INDEX(Partidos!$F$4:$F$107,MATCH($A13,Partidos!$A$4:$A$107,0))>INDEX(Partidos!$G$4:$G$107,MATCH($A13,Partidos!$A$4:$A$107,0))),AND($E13=$F13,INDEX(Partidos!$F$4:$F$107,MATCH($A13,Partidos!$A$4:$A$107,0))=INDEX(Partidos!$G$4:$G$107,MATCH($A13,Partidos!$A$4:$A$107,0))),AND($E13<$F13,INDEX(Partidos!$F$4:$F$107,MATCH($A13,Partidos!$A$4:$A$107,0))<INDEX(Partidos!$G$4:$G$107,MATCH($A13,Partidos!$A$4:$A$107,0)))),Puntuacion!$B$6,0))),IF(AND($E13=INDEX(Partidos!$F$4:$F$107,MATCH($A13,Partidos!$A$4:$A$107,0)),$F13=INDEX(Partidos!$G$4:$G$107,MATCH($A13,Partidos!$A$4:$A$107,0))),Puntuacion!$B$9,IF(($E13-$F13)=(INDEX(Partidos!$F$4:$F$107,MATCH($A13,Partidos!$A$4:$A$107,0))-INDEX(Partidos!$G$4:$G$107,MATCH($A13,Partidos!$A$4:$A$107,0))),Puntuacion!$B$10,IF(AND($H13<>"",$H13=INDEX(Partidos!$K$4:$K$107,MATCH($A13,Partidos!$A$4:$A$107,0))),Puntuacion!$B$11,0)))))),"") | H13: =IFERROR(INDEX(Álvaro!H$4:H$107,MATCH($A13,Álvaro!$A$4:$A$107,0)),"") | I13: =IFERROR(INDEX(Partidos!$J$4:$J$107,MATCH($A13,Partidos!$A$4:$A$107,0)),"") | J13: =IF(AND(INDEX(Partidos!$J$4:$J$107,MATCH($A13,Partidos!$A$4:$A$107,0))<>"Grupos",INDEX(Partidos!$H$4:$H$107,MATCH($A13,Partidos!$A$4:$A$107,0))="Finalizado",$H13<>"",$H13=INDEX(Partidos!$K$4:$K$107,MATCH($A13,Partidos!$A$4:$A$107,0))),1,0)
A14: 4 | B14: =IFERROR(INDEX(Partidos!$D$4:$D$107,MATCH($A14,Partidos!$A$4:$A$107,0)),"") | C14: =IFERROR(INDEX(Partidos!$E$4:$E$107,MATCH($A14,Partidos!$A$4:$A$107,0)),"") | D14: Papá | E14: =IFERROR(INDEX(Papá!F$4:F$107,MATCH($A14,Papá!$A$4:$A$107,0)),"") | F14: =IFERROR(INDEX(Papá!G$4:G$107,MATCH($A14,Papá!$A$4:$A$107,0)),"") | G14: =IFERROR(IF(INDEX(Partidos!$H$4:$H$107,MATCH($A14,Partidos!$A$4:$A$107,0))<>"Finalizado","",IF(OR(NOT(ISNUMBER($E14)),NOT(ISNUMBER($F14))),"",IF(INDEX(Partidos!$J$4:$J$107,MATCH($A14,Partidos!$A$4:$A$107,0))="Grupos",IF(AND($E14=INDEX(Partidos!$F$4:$F$107,MATCH($A14,Partidos!$A$4:$A$107,0)),$F14=INDEX(Partidos!$G$4:$G$107,MATCH($A14,Partidos!$A$4:$A$107,0))),Puntuacion!$B$4,IF(($E14-$F14)=(INDEX(Partidos!$F$4:$F$107,MATCH($A14,Partidos!$A$4:$A$107,0))-INDEX(Partidos!$G$4:$G$107,MATCH($A14,Partidos!$A$4:$A$107,0))),Puntuacion!$B$5,IF(OR(AND($E14>$F14,INDEX(Partidos!$F$4:$F$107,MATCH($A14,Partidos!$A$4:$A$107,0))>INDEX(Partidos!$G$4:$G$107,MATCH($A14,Partidos!$A$4:$A$107,0))),AND($E14=$F14,INDEX(Partidos!$F$4:$F$107,MATCH($A14,Partidos!$A$4:$A$107,0))=INDEX(Partidos!$G$4:$G$107,MATCH($A14,Partidos!$A$4:$A$107,0))),AND($E14<$F14,INDEX(Partidos!$F$4:$F$107,MATCH($A14,Partidos!$A$4:$A$107,0))<INDEX(Partidos!$G$4:$G$107,MATCH($A14,Partidos!$A$4:$A$107,0)))),Puntuacion!$B$6,0))),IF(AND($E14=INDEX(Partidos!$F$4:$F$107,MATCH($A14,Partidos!$A$4:$A$107,0)),$F14=INDEX(Partidos!$G$4:$G$107,MATCH($A14,Partidos!$A$4:$A$107,0))),Puntuacion!$B$9,IF(($E14-$F14)=(INDEX(Partidos!$F$4:$F$107,MATCH($A14,Partidos!$A$4:$A$107,0))-INDEX(Partidos!$G$4:$G$107,MATCH($A14,Partidos!$A$4:$A$107,0))),Puntuacion!$B$10,IF(AND($H14<>"",$H14=INDEX(Partidos!$K$4:$K$107,MATCH($A14,Partidos!$A$4:$A$107,0))),Puntuacion!$B$11,0)))))),"") | H14: =IFERROR(INDEX(Papá!H$4:H$107,MATCH($A14,Papá!$A$4:$A$107,0)),"") | I14: =IFERROR(INDEX(Partidos!$J$4:$J$107,MATCH($A14,Partidos!$A$4:$A$107,0)),"") | J14: =IF(AND(INDEX(Partidos!$J$4:$J$107,MATCH($A14,Partidos!$A$4:$A$107,0))<>"Grupos",INDEX(Partidos!$H$4:$H$107,MATCH($A14,Partidos!$A$4:$A$107,0))="Finalizado",$H14<>"",$H14=INDEX(Partidos!$K$4:$K$107,MATCH($A14,Partidos!$A$4:$A$107,0))),1,0)
A15: 4 | B15: =IFERROR(INDEX(Partidos!$D$4:$D$107,MATCH($A15,Partidos!$A$4:$A$107,0)),"") | C15: =IFERROR(INDEX(Partidos!$E$4:$E$107,MATCH($A15,Partidos!$A$4:$A$107,0)),"") | D15: Diego | E15: =IFERROR(INDEX(Diego!F$4:F$107,MATCH($A15,Diego!$A$4:$A$107,0)),"") | F15: =IFERROR(INDEX(Diego!G$4:G$107,MATCH($A15,Diego!$A$4:$A$107,0)),"") | G15: =IFERROR(IF(INDEX(Partidos!$H$4:$H$107,MATCH($A15,Partidos!$A$4:$A$107,0))<>"Finalizado","",IF(OR(NOT(ISNUMBER($E15)),NOT(ISNUMBER($F15))),"",IF(INDEX(Partidos!$J$4:$J$107,MATCH($A15,Partidos!$A$4:$A$107,0))="Grupos",IF(AND($E15=INDEX(Partidos!$F$4:$F$107,MATCH($A15,Partidos!$A$4:$A$107,0)),$F15=INDEX(Partidos!$G$4:$G$107,MATCH($A15,Partidos!$A$4:$A$107,0))),Puntuacion!$B$4,IF(($E15-$F15)=(INDEX(Partidos!$F$4:$F$107,MATCH($A15,Partidos!$A$4:$A$107,0))-INDEX(Partidos!$G$4:$G$107,MATCH($A15,Partidos!$A$4:$A$107,0))),Puntuacion!$B$5,IF(OR(AND($E15>$F15,INDEX(Partidos!$F$4:$F$107,MATCH($A15,Partidos!$A$4:$A$107,0))>INDEX(Partidos!$G$4:$G$107,MATCH($A15,Partidos!$A$4:$A$107,0))),AND($E15=$F15,INDEX(Partidos!$F$4:$F$107,MATCH($A15,Partidos!$A$4:$A$107,0))=INDEX(Partidos!$G$4:$G$107,MATCH($A15,Partidos!$A$4:$A$107,0))),AND($E15<$F15,INDEX(Partidos!$F$4:$F$107,MATCH($A15,Partidos!$A$4:$A$107,0))<INDEX(Partidos!$G$4:$G$107,MATCH($A15,Partidos!$A$4:$A$107,0)))),Puntuacion!$B$6,0))),IF(AND($E15=INDEX(Partidos!$F$4:$F$107,MATCH($A15,Partidos!$A$4:$A$107,0)),$F15=INDEX(Partidos!$G$4:$G$107,MATCH($A15,Partidos!$A$4:$A$107,0))),Puntuacion!$B$9,IF(($E15-$F15)=(INDEX(Partidos!$F$4:$F$107,MATCH($A15,Partidos!$A$4:$A$107,0))-INDEX(Partidos!$G$4:$G$107,MATCH($A15,Partidos!$A$4:$A$107,0))),Puntuacion!$B$10,IF(AND($H15<>"",$H15=INDEX(Partidos!$K$4:$K$107,MATCH($A15,Partidos!$A$4:$A$107,0))),Puntuacion!$B$11,0)))))),"") | H15: =IFERROR(INDEX(Diego!H$4:H$107,MATCH($A15,Diego!$A$4:$A$107,0)),"") | I15: =IFERROR(INDEX(Partidos!$J$4:$J$107,MATCH($A15,Partidos!$A$4:$A$107,0)),"") | J15: =IF(AND(INDEX(Partidos!$J$4:$J$107,MATCH($A15,Partidos!$A$4:$A$107,0))<>"Grupos",INDEX(Partidos!$H$4:$H$107,MATCH($A15,Partidos!$A$4:$A$107,0))="Finalizado",$H15<>"",$H15=INDEX(Partidos!$K$4:$K$107,MATCH($A15,Partidos!$A$4:$A$107,0))),1,0)
A16: 5 | B16: =IFERROR(INDEX(Partidos!$D$4:$D$107,MATCH($A16,Partidos!$A$4:$A$107,0)),"") | C16: =IFERROR(INDEX(Partidos!$E$4:$E$107,MATCH($A16,Partidos!$A$4:$A$107,0)),"") | D16: Álvaro | E16: =IFERROR(INDEX(Álvaro!F$4:F$107,MATCH($A16,Álvaro!$A$4:$A$107,0)),"") | F16: =IFERROR(INDEX(Álvaro!G$4:G$107,MATCH($A16,Álvaro!$A$4:$A$107,0)),"") | G16: =IFERROR(IF(INDEX(Partidos!$H$4:$H$107,MATCH($A16,Partidos!$A$4:$A$107,0))<>"Finalizado","",IF(OR(NOT(ISNUMBER($E16)),NOT(ISNUMBER($F16))),"",IF(INDEX(Partidos!$J$4:$J$107,MATCH($A16,Partidos!$A$4:$A$107,0))="Grupos",IF(AND($E16=INDEX(Partidos!$F$4:$F$107,MATCH($A16,Partidos!$A$4:$A$107,0)),$F16=INDEX(Partidos!$G$4:$G$107,MATCH($A16,Partidos!$A$4:$A$107,0))),Puntuacion!$B$4,IF(($E16-$F16)=(INDEX(Partidos!$F$4:$F$107,MATCH($A16,Partidos!$A$4:$A$107,0))-INDEX(Partidos!$G$4:$G$107,MATCH($A16,Partidos!$A$4:$A$107,0))),Puntuacion!$B$5,IF(OR(AND($E16>$F16,INDEX(Partidos!$F$4:$F$107,MATCH($A16,Partidos!$A$4:$A$107,0))>INDEX(Partidos!$G$4:$G$107,MATCH($A16,Partidos!$A$4:$A$107,0))),AND($E16=$F16,INDEX(Partidos!$F$4:$F$107,MATCH($A16,Partidos!$A$4:$A$107,0))=INDEX(Partidos!$G$4:$G$107,MATCH($A16,Partidos!$A$4:$A$107,0))),AND($E16<$F16,INDEX(Partidos!$F$4:$F$107,MATCH($A16,Partidos!$A$4:$A$107,0))<INDEX(Partidos!$G$4:$G$107,MATCH($A16,Partidos!$A$4:$A$107,0)))),Puntuacion!$B$6,0))),IF(AND($E16=INDEX(Partidos!$F$4:$F$107,MATCH($A16,Partidos!$A$4:$A$107,0)),$F16=INDEX(Partidos!$G$4:$G$107,MATCH($A16,Partidos!$A$4:$A$107,0))),Puntuacion!$B$9,IF(($E16-$F16)=(INDEX(Partidos!$F$4:$F$107,MATCH($A16,Partidos!$A$4:$A$107,0))-INDEX(Partidos!$G$4:$G$107,MATCH($A16,Partidos!$A$4:$A$107,0))),Puntuacion!$B$10,IF(AND($H16<>"",$H16=INDEX(Partidos!$K$4:$K$107,MATCH($A16,Partidos!$A$4:$A$107,0))),Puntuacion!$B$11,0)))))),"") | H16: =IFERROR(INDEX(Álvaro!H$4:H$107,MATCH($A16,Álvaro!$A$4:$A$107,0)),"") | I16: =IFERROR(INDEX(Partidos!$J$4:$J$107,MATCH($A16,Partidos!$A$4:$A$107,0)),"") | J16: =IF(AND(INDEX(Partidos!$J$4:$J$107,MATCH($A16,Partidos!$A$4:$A$107,0))<>"Grupos",INDEX(Partidos!$H$4:$H$107,MATCH($A16,Partidos!$A$4:$A$107,0))="Finalizado",$H16<>"",$H16=INDEX(Partidos!$K$4:$K$107,MATCH($A16,Partidos!$A$4:$A$107,0))),1,0)
A17: 5 | B17: =IFERROR(INDEX(Partidos!$D$4:$D$107,MATCH($A17,Partidos!$A$4:$A$107,0)),"") | C17: =IFERROR(INDEX(Partidos!$E$4:$E$107,MATCH($A17,Partidos!$A$4:$A$107,0)),"") | D17: Papá | E17: =IFERROR(INDEX(Papá!F$4:F$107,MATCH($A17,Papá!$A$4:$A$107,0)),"") | F17: =IFERROR(INDEX(Papá!G$4:G$107,MATCH($A17,Papá!$A$4:$A$107,0)),"") | G17: =IFERROR(IF(INDEX(Partidos!$H$4:$H$107,MATCH($A17,Partidos!$A$4:$A$107,0))<>"Finalizado","",IF(OR(NOT(ISNUMBER($E17)),NOT(ISNUMBER($F17))),"",IF(INDEX(Partidos!$J$4:$J$107,MATCH($A17,Partidos!$A$4:$A$107,0))="Grupos",IF(AND($E17=INDEX(Partidos!$F$4:$F$107,MATCH($A17,Partidos!$A$4:$A$107,0)),$F17=INDEX(Partidos!$G$4:$G$107,MATCH($A17,Partidos!$A$4:$A$107,0))),Puntuacion!$B$4,IF(($E17-$F17)=(INDEX(Partidos!$F$4:$F$107,MATCH($A17,Partidos!$A$4:$A$107,0))-INDEX(Partidos!$G$4:$G$107,MATCH($A17,Partidos!$A$4:$A$107,0))),Puntuacion!$B$5,IF(OR(AND($E17>$F17,INDEX(Partidos!$F$4:$F$107,MATCH($A17,Partidos!$A$4:$A$107,0))>INDEX(Partidos!$G$4:$G$107,MATCH($A17,Partidos!$A$4:$A$107,0))),AND($E17=$F17,INDEX(Partidos!$F$4:$F$107,MATCH($A17,Partidos!$A$4:$A$107,0))=INDEX(Partidos!$G$4:$G$107,MATCH($A17,Partidos!$A$4:$A$107,0))),AND($E17<$F17,INDEX(Partidos!$F$4:$F$107,MATCH($A17,Partidos!$A$4:$A$107,0))<INDEX(Partidos!$G$4:$G$107,MATCH($A17,Partidos!$A$4:$A$107,0)))),Puntuacion!$B$6,0))),IF(AND($E17=INDEX(Partidos!$F$4:$F$107,MATCH($A17,Partidos!$A$4:$A$107,0)),$F17=INDEX(Partidos!$G$4:$G$107,MATCH($A17,Partidos!$A$4:$A$107,0))),Puntuacion!$B$9,IF(($E17-$F17)=(INDEX(Partidos!$F$4:$F$107,MATCH($A17,Partidos!$A$4:$A$107,0))-INDEX(Partidos!$G$4:$G$107,MATCH($A17,Partidos!$A$4:$A$107,0))),Puntuacion!$B$10,IF(AND($H17<>"",$H17=INDEX(Partidos!$K$4:$K$107,MATCH($A17,Partidos!$A$4:$A$107,0))),Puntuacion!$B$11,0)))))),"") | H17: =IFERROR(INDEX(Papá!H$4:H$107,MATCH($A17,Papá!$A$4:$A$107,0)),"") | I17: =IFERROR(INDEX(Partidos!$J$4:$J$107,MATCH($A17,Partidos!$A$4:$A$107,0)),"") | J17: =IF(AND(INDEX(Partidos!$J$4:$J$107,MATCH($A17,Partidos!$A$4:$A$107,0))<>"Grupos",INDEX(Partidos!$H$4:$H$107,MATCH($A17,Partidos!$A$4:$A$107,0))="Finalizado",$H17<>"",$H17=INDEX(Partidos!$K$4:$K$107,MATCH($A17,Partidos!$A$4:$A$107,0))),1,0)
A18: 5 | B18: =IFERROR(INDEX(Partidos!$D$4:$D$107,MATCH($A18,Partidos!$A$4:$A$107,0)),"") | C18: =IFERROR(INDEX(Partidos!$E$4:$E$107,MATCH($A18,Partidos!$A$4:$A$107,0)),"") | D18: Diego | E18: =IFERROR(INDEX(Diego!F$4:F$107,MATCH($A18,Diego!$A$4:$A$107,0)),"") | F18: =IFERROR(INDEX(Diego!G$4:G$107,MATCH($A18,Diego!$A$4:$A$107,0)),"") | G18: =IFERROR(IF(INDEX(Partidos!$H$4:$H$107,MATCH($A18,Partidos!$A$4:$A$107,0))<>"Finalizado","",IF(OR(NOT(ISNUMBER($E18)),NOT(ISNUMBER($F18))),"",IF(INDEX(Partidos!$J$4:$J$107,MATCH($A18,Partidos!$A$4:$A$107,0))="Grupos",IF(AND($E18=INDEX(Partidos!$F$4:$F$107,MATCH($A18,Partidos!$A$4:$A$107,0)),$F18=INDEX(Partidos!$G$4:$G$107,MATCH($A18,Partidos!$A$4:$A$107,0))),Puntuacion!$B$4,IF(($E18-$F18)=(INDEX(Partidos!$F$4:$F$107,MATCH($A18,Partidos!$A$4:$A$107,0))-INDEX(Partidos!$G$4:$G$107,MATCH($A18,Partidos!$A$4:$A$107,0))),Puntuacion!$B$5,IF(OR(AND($E18>$F18,INDEX(Partidos!$F$4:$F$107,MATCH($A18,Partidos!$A$4:$A$107,0))>INDEX(Partidos!$G$4:$G$107,MATCH($A18,Partidos!$A$4:$A$107,0))),AND($E18=$F18,INDEX(Partidos!$F$4:$F$107,MATCH($A18,Partidos!$A$4:$A$107,0))=INDEX(Partidos!$G$4:$G$107,MATCH($A18,Partidos!$A$4:$A$107,0))),AND($E18<$F18,INDEX(Partidos!$F$4:$F$107,MATCH($A18,Partidos!$A$4:$A$107,0))<INDEX(Partidos!$G$4:$G$107,MATCH($A18,Partidos!$A$4:$A$107,0)))),Puntuacion!$B$6,0))),IF(AND($E18=INDEX(Partidos!$F$4:$F$107,MATCH($A18,Partidos!$A$4:$A$107,0)),$F18=INDEX(Partidos!$G$4:$G$107,MATCH($A18,Partidos!$A$4:$A$107,0))),Puntuacion!$B$9,IF(($E18-$F18)=(INDEX(Partidos!$F$4:$F$107,MATCH($A18,Partidos!$A$4:$A$107,0))-INDEX(Partidos!$G$4:$G$107,MATCH($A18,Partidos!$A$4:$A$107,0))),Puntuacion!$B$10,IF(AND($H18<>"",$H18=INDEX(Partidos!$K$4:$K$107,MATCH($A18,Partidos!$A$4:$A$107,0))),Puntuacion!$B$11,0)))))),"") | H18: =IFERROR(INDEX(Diego!H$4:H$107,MATCH($A18,Diego!$A$4:$A$107,0)),"") | I18: =IFERROR(INDEX(Partidos!$J$4:$J$107,MATCH($A18,Partidos!$A$4:$A$107,0)),"") | J18: =IF(AND(INDEX(Partidos!$J$4:$J$107,MATCH($A18,Partidos!$A$4:$A$107,0))<>"Grupos",INDEX(Partidos!$H$4:$H$107,MATCH($A18,Partidos!$A$4:$A$107,0))="Finalizado",$H18<>"",$H18=INDEX(Partidos!$K$4:$K$107,MATCH($A18,Partidos!$A$4:$A$107,0))),1,0)
A19: 6 | B19: =IFERROR(INDEX(Partidos!$D$4:$D$107,MATCH($A19,Partidos!$A$4:$A$107,0)),"") | C19: =IFERROR(INDEX(Partidos!$E$4:$E$107,MATCH($A19,Partidos!$A$4:$A$107,0)),"") | D19: Álvaro | E19: =IFERROR(INDEX(Álvaro!F$4:F$107,MATCH($A19,Álvaro!$A$4:$A$107,0)),"") | F19: =IFERROR(INDEX(Álvaro!G$4:G$107,MATCH($A19,Álvaro!$A$4:$A$107,0)),"") | G19: =IFERROR(IF(INDEX(Partidos!$H$4:$H$107,MATCH($A19,Partidos!$A$4:$A$107,0))<>"Finalizado","",IF(OR(NOT(ISNUMBER($E19)),NOT(ISNUMBER($F19))),"",IF(INDEX(Partidos!$J$4:$J$107,MATCH($A19,Partidos!$A$4:$A$107,0))="Grupos",IF(AND($E19=INDEX(Partidos!$F$4:$F$107,MATCH($A19,Partidos!$A$4:$A$107,0)),$F19=INDEX(Partidos!$G$4:$G$107,MATCH($A19,Partidos!$A$4:$A$107,0))),Puntuacion!$B$4,IF(($E19-$F19)=(INDEX(Partidos!$F$4:$F$107,MATCH($A19,Partidos!$A$4:$A$107,0))-INDEX(Partidos!$G$4:$G$107,MATCH($A19,Partidos!$A$4:$A$107,0))),Puntuacion!$B$5,IF(OR(AND($E19>$F19,INDEX(Partidos!$F$4:$F$107,MATCH($A19,Partidos!$A$4:$A$107,0))>INDEX(Partidos!$G$4:$G$107,MATCH($A19,Partidos!$A$4:$A$107,0))),AND($E19=$F19,INDEX(Partidos!$F$4:$F$107,MATCH($A19,Partidos!$A$4:$A$107,0))=INDEX(Partidos!$G$4:$G$107,MATCH($A19,Partidos!$A$4:$A$107,0))),AND($E19<$F19,INDEX(Partidos!$F$4:$F$107,MATCH($A19,Partidos!$A$4:$A$107,0))<INDEX(Partidos!$G$4:$G$107,MATCH($A19,Partidos!$A$4:$A$107,0)))),Puntuacion!$B$6,0))),IF(AND($E19=INDEX(Partidos!$F$4:$F$107,MATCH($A19,Partidos!$A$4:$A$107,0)),$F19=INDEX(Partidos!$G$4:$G$107,MATCH($A19,Partidos!$A$4:$A$107,0))),Puntuacion!$B$9,IF(($E19-$F19)=(INDEX(Partidos!$F$4:$F$107,MATCH($A19,Partidos!$A$4:$A$107,0))-INDEX(Partidos!$G$4:$G$107,MATCH($A19,Partidos!$A$4:$A$107,0))),Puntuacion!$B$10,IF(AND($H19<>"",$H19=INDEX(Partidos!$K$4:$K$107,MATCH($A19,Partidos!$A$4:$A$107,0))),Puntuacion!$B$11,0)))))),"") | H19: =IFERROR(INDEX(Álvaro!H$4:H$107,MATCH($A19,Álvaro!$A$4:$A$107,0)),"") | I19: =IFERROR(INDEX(Partidos!$J$4:$J$107,MATCH($A19,Partidos!$A$4:$A$107,0)),"") | J19: =IF(AND(INDEX(Partidos!$J$4:$J$107,MATCH($A19,Partidos!$A$4:$A$107,0))<>"Grupos",INDEX(Partidos!$H$4:$H$107,MATCH($A19,Partidos!$A$4:$A$107,0))="Finalizado",$H19<>"",$H19=INDEX(Partidos!$K$4:$K$107,MATCH($A19,Partidos!$A$4:$A$107,0))),1,0)
A20: 6 | B20: =IFERROR(INDEX(Partidos!$D$4:$D$107,MATCH($A20,Partidos!$A$4:$A$107,0)),"") | C20: =IFERROR(INDEX(Partidos!$E$4:$E$107,MATCH($A20,Partidos!$A$4:$A$107,0)),"") | D20: Papá | E20: =IFERROR(INDEX(Papá!F$4:F$107,MATCH($A20,Papá!$A$4:$A$107,0)),"") | F20: =IFERROR(INDEX(Papá!G$4:G$107,MATCH($A20,Papá!$A$4:$A$107,0)),"") | G20: =IFERROR(IF(INDEX(Partidos!$H$4:$H$107,MATCH($A20,Partidos!$A$4:$A$107,0))<>"Finalizado","",IF(OR(NOT(ISNUMBER($E20)),NOT(ISNUMBER($F20))),"",IF(INDEX(Partidos!$J$4:$J$107,MATCH($A20,Partidos!$A$4:$A$107,0))="Grupos",IF(AND($E20=INDEX(Partidos!$F$4:$F$107,MATCH($A20,Partidos!$A$4:$A$107,0)),$F20=INDEX(Partidos!$G$4:$G$107,MATCH($A20,Partidos!$A$4:$A$107,0))),Puntuacion!$B$4,IF(($E20-$F20)=(INDEX(Partidos!$F$4:$F$107,MATCH($A20,Partidos!$A$4:$A$107,0))-INDEX(Partidos!$G$4:$G$107,MATCH($A20,Partidos!$A$4:$A$107,0))),Puntuacion!$B$5,IF(OR(AND($E20>$F20,INDEX(Partidos!$F$4:$F$107,MATCH($A20,Partidos!$A$4:$A$107,0))>INDEX(Partidos!$G$4:$G$107,MATCH($A20,Partidos!$A$4:$A$107,0))),AND($E20=$F20,INDEX(Partidos!$F$4:$F$107,MATCH($A20,Partidos!$A$4:$A$107,0))=INDEX(Partidos!$G$4:$G$107,MATCH($A20,Partidos!$A$4:$A$107,0))),AND($E20<$F20,INDEX(Partidos!$F$4:$F$107,MATCH($A20,Partidos!$A$4:$A$107,0))<INDEX(Partidos!$G$4:$G$107,MATCH($A20,Partidos!$A$4:$A$107,0)))),Puntuacion!$B$6,0))),IF(AND($E20=INDEX(Partidos!$F$4:$F$107,MATCH($A20,Partidos!$A$4:$A$107,0)),$F20=INDEX(Partidos!$G$4:$G$107,MATCH($A20,Partidos!$A$4:$A$107,0))),Puntuacion!$B$9,IF(($E20-$F20)=(INDEX(Partidos!$F$4:$F$107,MATCH($A20,Partidos!$A$4:$A$107,0))-INDEX(Partidos!$G$4:$G$107,MATCH($A20,Partidos!$A$4:$A$107,0))),Puntuacion!$B$10,IF(AND($H20<>"",$H20=INDEX(Partidos!$K$4:$K$107,MATCH($A20,Partidos!$A$4:$A$107,0))),Puntuacion!$B$11,0)))))),"") | H20: =IFERROR(INDEX(Papá!H$4:H$107,MATCH($A20,Papá!$A$4:$A$107,0)),"") | I20: =IFERROR(INDEX(Partidos!$J$4:$J$107,MATCH($A20,Partidos!$A$4:$A$107,0)),"") | J20: =IF(AND(INDEX(Partidos!$J$4:$J$107,MATCH($A20,Partidos!$A$4:$A$107,0))<>"Grupos",INDEX(Partidos!$H$4:$H$107,MATCH($A20,Partidos!$A$4:$A$107,0))="Finalizado",$H20<>"",$H20=INDEX(Partidos!$K$4:$K$107,MATCH($A20,Partidos!$A$4:$A$107,0))),1,0)
A21: 6 | B21: =IFERROR(INDEX(Partidos!$D$4:$D$107,MATCH($A21,Partidos!$A$4:$A$107,0)),"") | C21: =IFERROR(INDEX(Partidos!$E$4:$E$107,MATCH($A21,Partidos!$A$4:$A$107,0)),"") | D21: Diego | E21: =IFERROR(INDEX(Diego!F$4:F$107,MATCH($A21,Diego!$A$4:$A$107,0)),"") | F21: =IFERROR(INDEX(Diego!G$4:G$107,MATCH($A21,Diego!$A$4:$A$107,0)),"") | G21: =IFERROR(IF(INDEX(Partidos!$H$4:$H$107,MATCH($A21,Partidos!$A$4:$A$107,0))<>"Finalizado","",IF(OR(NOT(ISNUMBER($E21)),NOT(ISNUMBER($F21))),"",IF(INDEX(Partidos!$J$4:$J$107,MATCH($A21,Partidos!$A$4:$A$107,0))="Grupos",IF(AND($E21=INDEX(Partidos!$F$4:$F$107,MATCH($A21,Partidos!$A$4:$A$107,0)),$F21=INDEX(Partidos!$G$4:$G$107,MATCH($A21,Partidos!$A$4:$A$107,0))),Puntuacion!$B$4,IF(($E21-$F21)=(INDEX(Partidos!$F$4:$F$107,MATCH($A21,Partidos!$A$4:$A$107,0))-INDEX(Partidos!$G$4:$G$107,MATCH($A21,Partidos!$A$4:$A$107,0))),Puntuacion!$B$5,IF(OR(AND($E21>$F21,INDEX(Partidos!$F$4:$F$107,MATCH($A21,Partidos!$A$4:$A$107,0))>INDEX(Partidos!$G$4:$G$107,MATCH($A21,Partidos!$A$4:$A$107,0))),AND($E21=$F21,INDEX(Partidos!$F$4:$F$107,MATCH($A21,Partidos!$A$4:$A$107,0))=INDEX(Partidos!$G$4:$G$107,MATCH($A21,Partidos!$A$4:$A$107,0))),AND($E21<$F21,INDEX(Partidos!$F$4:$F$107,MATCH($A21,Partidos!$A$4:$A$107,0))<INDEX(Partidos!$G$4:$G$107,MATCH($A21,Partidos!$A$4:$A$107,0)))),Puntuacion!$B$6,0))),IF(AND($E21=INDEX(Partidos!$F$4:$F$107,MATCH($A21,Partidos!$A$4:$A$107,0)),$F21=INDEX(Partidos!$G$4:$G$107,MATCH($A21,Partidos!$A$4:$A$107,0))),Puntuacion!$B$9,IF(($E21-$F21)=(INDEX(Partidos!$F$4:$F$107,MATCH($A21,Partidos!$A$4:$A$107,0))-INDEX(Partidos!$G$4:$G$107,MATCH($A21,Partidos!$A$4:$A$107,0))),Puntuacion!$B$10,IF(AND($H21<>"",$H21=INDEX(Partidos!$K$4:$K$107,MATCH($A21,Partidos!$A$4:$A$107,0))),Puntuacion!$B$11,0)))))),"") | H21: =IFERROR(INDEX(Diego!H$4:H$107,MATCH($A21,Diego!$A$4:$A$107,0)),"") | I21: =IFERROR(INDEX(Partidos!$J$4:$J$107,MATCH($A21,Partidos!$A$4:$A$107,0)),"") | J21: =IF(AND(INDEX(Partidos!$J$4:$J$107,MATCH($A21,Partidos!$A$4:$A$107,0))<>"Grupos",INDEX(Partidos!$H$4:$H$107,MATCH($A21,Partidos!$A$4:$A$107,0))="Finalizado",$H21<>"",$H21=INDEX(Partidos!$K$4:$K$107,MATCH($A21,Partidos!$A$4:$A$107,0))),1,0)
A22: 7 | B22: =IFERROR(INDEX(Partidos!$D$4:$D$107,MATCH($A22,Partidos!$A$4:$A$107,0)),"") | C22: =IFERROR(INDEX(Partidos!$E$4:$E$107,MATCH($A22,Partidos!$A$4:$A$107,0)),"") | D22: Álvaro | E22: =IFERROR(INDEX(Álvaro!F$4:F$107,MATCH($A22,Álvaro!$A$4:$A$107,0)),"") | F22: =IFERROR(INDEX(Álvaro!G$4:G$107,MATCH($A22,Álvaro!$A$4:$A$107,0)),"") | G22: =IFERROR(IF(INDEX(Partidos!$H$4:$H$107,MATCH($A22,Partidos!$A$4:$A$107,0))<>"Finalizado","",IF(OR(NOT(ISNUMBER($E22)),NOT(ISNUMBER($F22))),"",IF(INDEX(Partidos!$J$4:$J$107,MATCH($A22,Partidos!$A$4:$A$107,0))="Grupos",IF(AND($E22=INDEX(Partidos!$F$4:$F$107,MATCH($A22,Partidos!$A$4:$A$107,0)),$F22=INDEX(Partidos!$G$4:$G$107,MATCH($A22,Partidos!$A$4:$A$107,0))),Puntuacion!$B$4,IF(($E22-$F22)=(INDEX(Partidos!$F$4:$F$107,MATCH($A22,Partidos!$A$4:$A$107,0))-INDEX(Partidos!$G$4:$G$107,MATCH($A22,Partidos!$A$4:$A$107,0))),Puntuacion!$B$5,IF(OR(AND($E22>$F22,INDEX(Partidos!$F$4:$F$107,MATCH($A22,Partidos!$A$4:$A$107,0))>INDEX(Partidos!$G$4:$G$107,MATCH($A22,Partidos!$A$4:$A$107,0))),AND($E22=$F22,INDEX(Partidos!$F$4:$F$107,MATCH($A22,Partidos!$A$4:$A$107,0))=INDEX(Partidos!$G$4:$G$107,MATCH($A22,Partidos!$A$4:$A$107,0))),AND($E22<$F22,INDEX(Partidos!$F$4:$F$107,MATCH($A22,Partidos!$A$4:$A$107,0))<INDEX(Partidos!$G$4:$G$107,MATCH($A22,Partidos!$A$4:$A$107,0)))),Puntuacion!$B$6,0))),IF(AND($E22=INDEX(Partidos!$F$4:$F$107,MATCH($A22,Partidos!$A$4:$A$107,0)),$F22=INDEX(Partidos!$G$4:$G$107,MATCH($A22,Partidos!$A$4:$A$107,0))),Puntuacion!$B$9,IF(($E22-$F22)=(INDEX(Partidos!$F$4:$F$107,MATCH($A22,Partidos!$A$4:$A$107,0))-INDEX(Partidos!$G$4:$G$107,MATCH($A22,Partidos!$A$4:$A$107,0))),Puntuacion!$B$10,IF(AND($H22<>"",$H22=INDEX(Partidos!$K$4:$K$107,MATCH($A22,Partidos!$A$4:$A$107,0))),Puntuacion!$B$11,0)))))),"") | H22: =IFERROR(INDEX(Álvaro!H$4:H$107,MATCH($A22,Álvaro!$A$4:$A$107,0)),"") | I22: =IFERROR(INDEX(Partidos!$J$4:$J$107,MATCH($A22,Partidos!$A$4:$A$107,0)),"") | J22: =IF(AND(INDEX(Partidos!$J$4:$J$107,MATCH($A22,Partidos!$A$4:$A$107,0))<>"Grupos",INDEX(Partidos!$H$4:$H$107,MATCH($A22,Partidos!$A$4:$A$107,0))="Finalizado",$H22<>"",$H22=INDEX(Partidos!$K$4:$K$107,MATCH($A22,Partidos!$A$4:$A$107,0))),1,0)
A23: 7 | B23: =IFERROR(INDEX(Partidos!$D$4:$D$107,MATCH($A23,Partidos!$A$4:$A$107,0)),"") | C23: =IFERROR(INDEX(Partidos!$E$4:$E$107,MATCH($A23,Partidos!$A$4:$A$107,0)),"") | D23: Papá | E23: =IFERROR(INDEX(Papá!F$4:F$107,MATCH($A23,Papá!$A$4:$A$107,0)),"") | F23: =IFERROR(INDEX(Papá!G$4:G$107,MATCH($A23,Papá!$A$4:$A$107,0)),"") | G23: =IFERROR(IF(INDEX(Partidos!$H$4:$H$107,MATCH($A23,Partidos!$A$4:$A$107,0))<>"Finalizado","",IF(OR(NOT(ISNUMBER($E23)),NOT(ISNUMBER($F23))),"",IF(INDEX(Partidos!$J$4:$J$107,MATCH($A23,Partidos!$A$4:$A$107,0))="Grupos",IF(AND($E23=INDEX(Partidos!$F$4:$F$107,MATCH($A23,Partidos!$A$4:$A$107,0)),$F23=INDEX(Partidos!$G$4:$G$107,MATCH($A23,Partidos!$A$4:$A$107,0))),Puntuacion!$B$4,IF(($E23-$F23)=(INDEX(Partidos!$F$4:$F$107,MATCH($A23,Partidos!$A$4:$A$107,0))-INDEX(Partidos!$G$4:$G$107,MATCH($A23,Partidos!$A$4:$A$107,0))),Puntuacion!$B$5,IF(OR(AND($E23>$F23,INDEX(Partidos!$F$4:$F$107,MATCH($A23,Partidos!$A$4:$A$107,0))>INDEX(Partidos!$G$4:$G$107,MATCH($A23,Partidos!$A$4:$A$107,0))),AND($E23=$F23,INDEX(Partidos!$F$4:$F$107,MATCH($A23,Partidos!$A$4:$A$107,0))=INDEX(Partidos!$G$4:$G$107,MATCH($A23,Partidos!$A$4:$A$107,0))),AND($E23<$F23,INDEX(Partidos!$F$4:$F$107,MATCH($A23,Partidos!$A$4:$A$107,0))<INDEX(Partidos!$G$4:$G$107,MATCH($A23,Partidos!$A$4:$A$107,0)))),Puntuacion!$B$6,0))),IF(AND($E23=INDEX(Partidos!$F$4:$F$107,MATCH($A23,Partidos!$A$4:$A$107,0)),$F23=INDEX(Partidos!$G$4:$G$107,MATCH($A23,Partidos!$A$4:$A$107,0))),Puntuacion!$B$9,IF(($E23-$F23)=(INDEX(Partidos!$F$4:$F$107,MATCH($A23,Partidos!$A$4:$A$107,0))-INDEX(Partidos!$G$4:$G$107,MATCH($A23,Partidos!$A$4:$A$107,0))),Puntuacion!$B$10,IF(AND($H23<>"",$H23=INDEX(Partidos!$K$4:$K$107,MATCH($A23,Partidos!$A$4:$A$107,0))),Puntuacion!$B$11,0)))))),"") | H23: =IFERROR(INDEX(Papá!H$4:H$107,MATCH($A23,Papá!$A$4:$A$107,0)),"") | I23: =IFERROR(INDEX(Partidos!$J$4:$J$107,MATCH($A23,Partidos!$A$4:$A$107,0)),"") | J23: =IF(AND(INDEX(Partidos!$J$4:$J$107,MATCH($A23,Partidos!$A$4:$A$107,0))<>"Grupos",INDEX(Partidos!$H$4:$H$107,MATCH($A23,Partidos!$A$4:$A$107,0))="Finalizado",$H23<>"",$H23=INDEX(Partidos!$K$4:$K$107,MATCH($A23,Partidos!$A$4:$A$107,0))),1,0)
A24: 7 | B24: =IFERROR(INDEX(Partidos!$D$4:$D$107,MATCH($A24,Partidos!$A$4:$A$107,0)),"") | C24: =IFERROR(INDEX(Partidos!$E$4:$E$107,MATCH($A24,Partidos!$A$4:$A$107,0)),"") | D24: Diego | E24: =IFERROR(INDEX(Diego!F$4:F$107,MATCH($A24,Diego!$A$4:$A$107,0)),"") | F24: =IFERROR(INDEX(Diego!G$4:G$107,MATCH($A24,Diego!$A$4:$A$107,0)),"") | G24: =IFERROR(IF(INDEX(Partidos!$H$4:$H$107,MATCH($A24,Partidos!$A$4:$A$107,0))<>"Finalizado","",IF(OR(NOT(ISNUMBER($E24)),NOT(ISNUMBER($F24))),"",IF(INDEX(Partidos!$J$4:$J$107,MATCH($A24,Partidos!$A$4:$A$107,0))="Grupos",IF(AND($E24=INDEX(Partidos!$F$4:$F$107,MATCH($A24,Partidos!$A$4:$A$107,0)),$F24=INDEX(Partidos!$G$4:$G$107,MATCH($A24,Partidos!$A$4:$A$107,0))),Puntuacion!$B$4,IF(($E24-$F24)=(INDEX(Partidos!$F$4:$F$107,MATCH($A24,Partidos!$A$4:$A$107,0))-INDEX(Partidos!$G$4:$G$107,MATCH($A24,Partidos!$A$4:$A$107,0))),Puntuacion!$B$5,IF(OR(AND($E24>$F24,INDEX(Partidos!$F$4:$F$107,MATCH($A24,Partidos!$A$4:$A$107,0))>INDEX(Partidos!$G$4:$G$107,MATCH($A24,Partidos!$A$4:$A$107,0))),AND($E24=$F24,INDEX(Partidos!$F$4:$F$107,MATCH($A24,Partidos!$A$4:$A$107,0))=INDEX(Partidos!$G$4:$G$107,MATCH($A24,Partidos!$A$4:$A$107,0))),AND($E24<$F24,INDEX(Partidos!$F$4:$F$107,MATCH($A24,Partidos!$A$4:$A$107,0))<INDEX(Partidos!$G$4:$G$107,MATCH($A24,Partidos!$A$4:$A$107,0)))),Puntuacion!$B$6,0))),IF(AND($E24=INDEX(Partidos!$F$4:$F$107,MATCH($A24,Partidos!$A$4:$A$107,0)),$F24=INDEX(Partidos!$G$4:$G$107,MATCH($A24,Partidos!$A$4:$A$107,0))),Puntuacion!$B$9,IF(($E24-$F24)=(INDEX(Partidos!$F$4:$F$107,MATCH($A24,Partidos!$A$4:$A$107,0))-INDEX(Partidos!$G$4:$G$107,MATCH($A24,Partidos!$A$4:$A$107,0))),Puntuacion!$B$10,IF(AND($H24<>"",$H24=INDEX(Partidos!$K$4:$K$107,MATCH($A24,Partidos!$A$4:$A$107,0))),Puntuacion!$B$11,0)))))),"") | H24: =IFERROR(INDEX(Diego!H$4:H$107,MATCH($A24,Diego!$A$4:$A$107,0)),"") | I24: =IFERROR(INDEX(Partidos!$J$4:$J$107,MATCH($A24,Partidos!$A$4:$A$107,0)),"") | J24: =IF(AND(INDEX(Partidos!$J$4:$J$107,MATCH($A24,Partidos!$A$4:$A$107,0))<>"Grupos",INDEX(Partidos!$H$4:$H$107,MATCH($A24,Partidos!$A$4:$A$107,0))="Finalizado",$H24<>"",$H24=INDEX(Partidos!$K$4:$K$107,MATCH($A24,Partidos!$A$4:$A$107,0))),1,0)
