Workbook

Sheet Portada
A29: PORRA MUNDIAL 2026
A32: FIFA WORLD CUP 26 · USA · CANADÁ · MÉXICO
A35: Porra privada entre amigos · Pronósticos, clasificación automática y apuestas especiales
A38: Jugadores: Álvaro · Pepe · Patri · Kike · Quintero · Nacho · Luis · Felipe · Simón · Muni · Fer

Sheet Instrucciones
A1: INSTRUCCIONES
A2: Guía paso a paso para usar la porra sin tocar fórmulas.
A3: 1 | B3: Empieza por tu pestaña
B4: Busca la pestaña con tu nombre. Ahí rellenas todo lo tuyo: goles de cada partido, clasificado en eliminatorias y apuestas especiales. Solo escribe en celdas amarillas. Las celdas azules son fórmulas y las grises son referencias de otras pestañas.
A6: 2 | B6: Pronósticos de partidos
B7: En fase de grupos rellena Mis goles local y Mis goles visit.; la columna Clasificado aparece con '-' y no se usa. En octavos, cuartos, semifinales y final, además de los goles a 90 minutos, elige Clasificado: Local o Visitante.
A9: 3 | B9: Apuestas especiales
B10: En la parte inferior de tu pestaña escribe tus apuestas especiales antes de que empiece el torneo. El resultado oficial de esas apuestas se rellena después en Resumen, dentro del bloque Apuestas especiales.
A12: 4 | B12: Resultados reales
B13: La persona que administre la porra usa Partidos. En grupos rellena Resultado local y Resultado visitante. En eliminatorias rellena también Clasificado, que es quien pasa la ronda aunque sea en prórroga o penaltis.
A15: 5 | B15: Qué mirar durante el torneo
B16: Resumen es el dashboard principal: líder, clasificación completa, últimos partidos, análisis por jugador y apuestas especiales. Pronosticos consolida lo que ha puesto cada jugador y es de solo lectura.
A18: 6 | B18: Configuración y hojas técnicas
B19: Puntuacion permite cambiar los puntos de cada regla. Helpers >> separa las hojas de trabajo. _Helpers contiene cálculos internos y no requiere input.
A22: Pestañas con input: tu nombre, Partidos, Resumen (solo resultados oficiales de apuestas especiales) y Puntuacion.
A23: Pestañas sin input: Pronosticos, Helpers >> y _Helpers. Regla visual: amarillo = input; azul = fórmula; gris = referencia.
A24: Requisitos: Microsoft Excel 2010 o superior (Windows/Mac). No usa macros.

Sheet Resumen
A1: RESUMEN — DASHBOARD
A2: Todo se calcula solo. Lo único editable aquí es, en amarillo, el resultado oficial de las apuestas especiales.
A4: Indicadores del torneo
A5: LÍDER | C5: PUNTOS DEL LÍDER | E5: PARTIDOS JUGADOS | G5: PARTIDOS PENDIENTES | I5: PROGRESO TORNEO | K5: MEDIA PTS/PARTIDO LÍDER | M5: JUGADORES
A6: =_Helpers!$A$15 | C6: =_Helpers!$B$15 | E6: =COUNTIF(Partidos!$H$4:$H$107,"Finalizado") | G6: =104-COUNTIF(Partidos!$H$4:$H$107,"Finalizado") | I6: =IF(COUNTIF(Partidos!$H$4:$H$107,"Finalizado")=0,0,COUNTIF(Partidos!$H$4:$H$107,"Finalizado")/104) | K6: =IF(COUNTIF(Partidos!$H$4:$H$107,"Finalizado")=0,"",ROUND(_Helpers!$B$15/COUNTIF(Partidos!$H$4:$H$107,"Finalizado"),2)) | M6: 11
A8: Clasificación general | K8: Últimos partidos jugados
A9: Pos. | B9: Jugador | C9: Puntos | D9: Exactos | E9: Parciales | F9: Fallos | G9: % aciertos | H9: Medalla | I9: vs Líder | K9: Fecha | L9: Local | M9: Visitante | N9: Resultado
A10: 1 | B10: =_Helpers!$A$15 | C10: =_Helpers!$B$15 | D10: =_Helpers!$C$15 | E10: =_Helpers!$D$15 | F10: =_Helpers!$E$15 | G10: =_Helpers!$F$15 | H10: =IF(A10=1,"ORO",IF(A10=2,"PLATA",IF(A10=3,"BRONCE",""))) | I10: =IF(A10=1,0,$C$10-C10) | K10: =_Helpers!$X$101 | L10: =_Helpers!$U$101 | M10: =_Helpers!$V$101 | N10: =_Helpers!$W$101
A11: 2 | B11: =_Helpers!$A$16 | C11: =_Helpers!$B$16 | D11: =_Helpers!$C$16 | E11: =_Helpers!$D$16 | F11: =_Helpers!$E$16 | G11: =_Helpers!$F$16 | H11: =IF(A11=1,"ORO",IF(A11=2,"PLATA",IF(A11=3,"BRONCE",""))) | I11: =IF(A11=1,0,$C$10-C11) | K11: =_Helpers!$X$102 | L11: =_Helpers!$U$102 | M11: =_Helpers!$V$102 | N11: =_Helpers!$W$102
A12: 3 | B12: =_Helpers!$A$17 | C12: =_Helpers!$B$17 | D12: =_Helpers!$C$17 | E12: =_Helpers!$D$17 | F12: =_Helpers!$E$17 | G12: =_Helpers!$F$17 | H12: =IF(A12=1,"ORO",IF(A12=2,"PLATA",IF(A12=3,"BRONCE",""))) | I12: =IF(A12=1,0,$C$10-C12) | K12: =_Helpers!$X$103 | L12: =_Helpers!$U$103 | M12: =_Helpers!$V$103 | N12: =_Helpers!$W$103
A13: 4 | B13: =_Helpers!$A$18 | C13: =_Helpers!$B$18 | D13: =_Helpers!$C$18 | E13: =_Helpers!$D$18 | F13: =_Helpers!$E$18 | G13: =_Helpers!$F$18 | H13: =IF(A13=1,"ORO",IF(A13=2,"PLATA",IF(A13=3,"BRONCE",""))) | I13: =IF(A13=1,0,$C$10-C13) | K13: =_Helpers!$X$104 | L13: =_Helpers!$U$104 | M13: =_Helpers!$V$104 | N13: =_Helpers!$W$104
A14: 5 | B14: =_Helpers!$A$19 | C14: =_Helpers!$B$19 | D14: =_Helpers!$C$19 | E14: =_Helpers!$D$19 | F14: =_Helpers!$E$19 | G14: =_Helpers!$F$19 | H14: =IF(A14=1,"ORO",IF(A14=2,"PLATA",IF(A14=3,"BRONCE",""))) | I14: =IF(A14=1,0,$C$10-C14) | K14: =_Helpers!$X$105 | L14: =_Helpers!$U$105 | M14: =_Helpers!$V$105 | N14: =_Helpers!$W$105
A15: 6 | B15: =_Helpers!$A$20 | C15: =_Helpers!$B$20 | D15: =_Helpers!$C$20 | E15: =_Helpers!$D$20 | F15: =_Helpers!$E$20 | G15: =_Helpers!$F$20 | H15: =IF(A15=1,"ORO",IF(A15=2,"PLATA",IF(A15=3,"BRONCE",""))) | I15: =IF(A15=1,0,$C$10-C15)
A16: 7 | B16: =_Helpers!$A$21 | C16: =_Helpers!$B$21 | D16: =_Helpers!$C$21 | E16: =_Helpers!$D$21 | F16: =_Helpers!$E$21 | G16: =_Helpers!$F$21 | H16: =IF(A16=1,"ORO",IF(A16=2,"PLATA",IF(A16=3,"BRONCE",""))) | I16: =IF(A16=1,0,$C$10-C16)
A17: 8 | B17: =_Helpers!$A$22 | C17: =_Helpers!$B$22 | D17: =_Helpers!$C$22 | E17: =_Helpers!$D$22 | F17: =_Helpers!$E$22 | G17: =_Helpers!$F$22 | H17: =IF(A17=1,"ORO",IF(A17=2,"PLATA",IF(A17=3,"BRONCE",""))) | I17: =IF(A17=1,0,$C$10-C17)
A18: 9 | B18: =_Helpers!$A$23 | C18: =_Helpers!$B$23 | D18: =_Helpers!$C$23 | E18: =_Helpers!$D$23 | F18: =_Helpers!$E$23 | G18: =_Helpers!$F$23 | H18: =IF(A18=1,"ORO",IF(A18=2,"PLATA",IF(A18=3,"BRONCE",""))) | I18: =IF(A18=1,0,$C$10-C18)
A19: 10 | B19: =_Helpers!$A$24 | C19: =_Helpers!$B$24 | D19: =_Helpers!$C$24 | E19: =_Helpers!$D$24 | F19: =_Helpers!$E$24 | G19: =_Helpers!$F$24 | H19: =IF(A19=1,"ORO",IF(A19=2,"PLATA",IF(A19=3,"BRONCE",""))) | I19: =IF(A19=1,0,$C$10-C19)
A20: 11 | B20: =_Helpers!$A$25 | C20: =_Helpers!$B$25 | D20: =_Helpers!$C$25 | E20: =_Helpers!$D$25 | F20: =_Helpers!$E$25 | G20: =_Helpers!$F$25 | H20: =IF(A20=1,"ORO",IF(A20=2,"PLATA",IF(A20=3,"BRONCE",""))) | I20: =IF(A20=1,0,$C$10-C20)
A22: Análisis por jugador
A23: Elige un jugador: | C23: Álvaro | D23: (escribe el nombre exacto de una pestaña)
A24: Métrica | B24: Valor
A25: Posición actual | B25: =IFERROR(MATCH($C$23,_Helpers!$A$15:$A$25,0),"")
A26: Puntos totales | B26: =IFERROR(INDEX(_Helpers!$E$2:$E$12,MATCH($C$23,_Helpers!$A$2:$A$12,0)),0)
A27: Puntos por partidos | B27: =IFERROR(INDEX(_Helpers!$B$2:$B$12,MATCH($C$23,_Helpers!$A$2:$A$12,0)),0)
A28: Bonus de rondas | B28: =IFERROR(INDEX(_Helpers!$C$2:$C$12,MATCH($C$23,_Helpers!$A$2:$A$12,0)),0)
A29: Puntos apuestas especiales | B29: =IFERROR(INDEX(_Helpers!$D$2:$D$12,MATCH($C$23,_Helpers!$A$2:$A$12,0)),0)
A30: Distancia al líder | B30: =IFERROR(_Helpers!$B$15-INDEX(_Helpers!$E$2:$E$12,MATCH($C$23,_Helpers!$A$2:$A$12,0)),0)
A32: Apuestas especiales · resultado oficial | F32: Puntos por apuestas especiales
A33: Categoría | B33: Resultado oficial | C33: Aciertos | D33: Estado | F33: Jugador | G33: Puntos | H33: Aciertos | I33: Peso
A34: Campeón del Mundial | C34: =IF($B34="",0,IF(Álvaro!$B$111=$B34,1,0)+IF(Pepe!$B$111=$B34,1,0)+IF(Patri!$B$111=$B34,1,0)+IF(Kike!$B$111=$B34,1,0)+IF(Quintero!$B$111=$B34,1,0)+IF(Nacho!$B$111=$B34,1,0)+IF(Luis!$B$111=$B34,1,0)+IF(Felipe!$B$111=$B34,1,0)+IF(Simón!$B$111=$B34,1,0)+IF(Muni!$B$111=$B34,1,0)+IF(Fer!$B$111=$B34,1,0)) | D34: =IF($B34="","Pendiente","Cargado") | F34: =_Helpers!$A$2 | G34: =_Helpers!$D$2 | H34: =IF(Puntuacion!$B$22=0,0,G34/Puntuacion!$B$22) | I34: =Puntuacion!$B$22
A35: Subcampeón | C35: =IF($B35="",0,IF(Álvaro!$B$112=$B35,1,0)+IF(Pepe!$B$112=$B35,1,0)+IF(Patri!$B$112=$B35,1,0)+IF(Kike!$B$112=$B35,1,0)+IF(Quintero!$B$112=$B35,1,0)+IF(Nacho!$B$112=$B35,1,0)+IF(Luis!$B$112=$B35,1,0)+IF(Felipe!$B$112=$B35,1,0)+IF(Simón!$B$112=$B35,1,0)+IF(Muni!$B$112=$B35,1,0)+IF(Fer!$B$112=$B35,1,0)) | D35: =IF($B35="","Pendiente","Cargado") | F35: =_Helpers!$A$3 | G35: =_Helpers!$D$3 | H35: =IF(Puntuacion!$B$22=0,0,G35/Puntuacion!$B$22) | I35: =Puntuacion!$B$22
A36: Tercer equipo | C36: =IF($B36="",0,IF(Álvaro!$B$113=$B36,1,0)+IF(Pepe!$B$113=$B36,1,0)+IF(Patri!$B$113=$B36,1,0)+IF(Kike!$B$113=$B36,1,0)+IF(Quintero!$B$113=$B36,1,0)+IF(Nacho!$B$113=$B36,1,0)+IF(Luis!$B$113=$B36,1,0)+IF(Felipe!$B$113=$B36,1,0)+IF(Simón!$B$113=$B36,1,0)+IF(Muni!$B$113=$B36,1,0)+IF(Fer!$B$113=$B36,1,0)) | D36: =IF($B36="","Pendiente","Cargado") | F36: =_Helpers!$A$4 | G36: =_Helpers!$D$4 | H36: =IF(Puntuacion!$B$22=0,0,G36/Puntuacion!$B$22) | I36: =Puntuacion!$B$22
A37: Balón de oro de la FIFA | C37: =IF($B37="",0,IF(Álvaro!$B$114=$B37,1,0)+IF(Pepe!$B$114=$B37,1,0)+IF(Patri!$B$114=$B37,1,0)+IF(Kike!$B$114=$B37,1,0)+IF(Quintero!$B$114=$B37,1,0)+IF(Nacho!$B$114=$B37,1,0)+IF(Luis!$B$114=$B37,1,0)+IF(Felipe!$B$114=$B37,1,0)+IF(Simón!$B$114=$B37,1,0)+IF(Muni!$B$114=$B37,1,0)+IF(Fer!$B$114=$B37,1,0)) | D37: =IF($B37="","Pendiente","Cargado") | F37: =_Helpers!$A$5 | G37: =_Helpers!$D$5 | H37: =IF(Puntuacion!$B$22=0,0,G37/Puntuacion!$B$22) | I37: =Puntuacion!$B$22
A38: Premio de la FIFA al mejor jugador joven | C38: =IF($B38="",0,IF(Álvaro!$B$115=$B38,1,0)+IF(Pepe!$B$115=$B38,1,0)+IF(Patri!$B$115=$B38,1,0)+IF(Kike!$B$115=$B38,1,0)+IF(Quintero!$B$115=$B38,1,0)+IF(Nacho!$B$115=$B38,1,0)+IF(Luis!$B$115=$B38,1,0)+IF(Felipe!$B$115=$B38,1,0)+IF(Simón!$B$115=$B38,1,0)+IF(Muni!$B$115=$B38,1,0)+IF(Fer!$B$115=$B38,1,0)) | D38: =IF($B38="","Pendiente","Cargado") | F38: =_Helpers!$A$6 | G38: =_Helpers!$D$6 | H38: =IF(Puntuacion!$B$22=0,0,G38/Puntuacion!$B$22) | I38: =Puntuacion!$B$22
A39: Guante de oro de la FIFA | C39: =IF($B39="",0,IF(Álvaro!$B$116=$B39,1,0)+IF(Pepe!$B$116=$B39,1,0)+IF(Patri!$B$116=$B39,1,0)+IF(Kike!$B$116=$B39,1,0)+IF(Quintero!$B$116=$B39,1,0)+IF(Nacho!$B$116=$B39,1,0)+IF(Luis!$B$116=$B39,1,0)+IF(Felipe!$B$116=$B39,1,0)+IF(Simón!$B$116=$B39,1,0)+IF(Muni!$B$116=$B39,1,0)+IF(Fer!$B$116=$B39,1,0)) | D39: =IF($B39="","Pendiente","Cargado") | F39: =_Helpers!$A$7 | G39: =_Helpers!$D$7 | H39: =IF(Puntuacion!$B$22=0,0,G39/Puntuacion!$B$22) | I39: =Puntuacion!$B$22
A40: Bota de oro de la FIFA | C40: =IF($B40="",0,IF(Álvaro!$B$117=$B40,1,0)+IF(Pepe!$B$117=$B40,1,0)+IF(Patri!$B$117=$B40,1,0)+IF(Kike!$B$117=$B40,1,0)+IF(Quintero!$B$117=$B40,1,0)+IF(Nacho!$B$117=$B40,1,0)+IF(Luis!$B$117=$B40,1,0)+IF(Felipe!$B$117=$B40,1,0)+IF(Simón!$B$117=$B40,1,0)+IF(Muni!$B$117=$B40,1,0)+IF(Fer!$B$117=$B40,1,0)) | D40: =IF($B40="","Pendiente","Cargado") | F40: =_Helpers!$A$8 | G40: =_Helpers!$D$8 | H40: =IF(Puntuacion!$B$22=0,0,G40/Puntuacion!$B$22) | I40: =Puntuacion!$B$22
A41: Máximo goleador España | C41: =IF($B41="",0,IF(Álvaro!$B$118=$B41,1,0)+IF(Pepe!$B$118=$B41,1,0)+IF(Patri!$B$118=$B41,1,0)+IF(Kike!$B$118=$B41,1,0)+IF(Quintero!$B$118=$B41,1,0)+IF(Nacho!$B$118=$B41,1,0)+IF(Luis!$B$118=$B41,1,0)+IF(Felipe!$B$118=$B41,1,0)+IF(Simón!$B$118=$B41,1,0)+IF(Muni!$B$118=$B41,1,0)+IF(Fer!$B$118=$B41,1,0)) | D41: =IF($B41="","Pendiente","Cargado") | F41: =_Helpers!$A$9 | G41: =_Helpers!$D$9 | H41: =IF(Puntuacion!$B$22=0,0,G41/Puntuacion!$B$22) | I41: =Puntuacion!$B$22
F42: =_Helpers!$A$10 | G42: =_Helpers!$D$10 | H42: =IF(Puntuacion!$B$22=0,0,G42/Puntuacion!$B$22) | I42: =Puntuacion!$B$22
F43: =_Helpers!$A$11 | G43: =_Helpers!$D$11 | H43: =IF(Puntuacion!$B$22=0,0,G43/Puntuacion!$B$22) | I43: =Puntuacion!$B$22
F44: =_Helpers!$A$12 | G44: =_Helpers!$D$12 | H44: =IF(Puntuacion!$B$22=0,0,G44/Puntuacion!$B$22) | I44: =Puntuacion!$B$22
...

Sheet Partidos
A1: CALENDARIO DE PARTIDOS
A2: Rellena resultados reales en amarillo; Clasificado solo aplica en eliminatorias.
A3: Nº partido | B3: Fecha | C3: Hora | D3: Equipo local | E3: Equipo visitante | F3: Resultado local | G3: Resultado visitante | H3: Estado | I3: Jornada | J3: Fase | K3: Clasificado
A4: 1 | B4: 11/06/2026 | C4: 13:00 | D4: México | E4: Sudáfrica | F4: 2 | G4: 0 | H4: =IF(AND(ISNUMBER(F4),ISNUMBER(G4)),"Finalizado","Pendiente") | I4: 1 | J4: Grupos | K4: -
A5: 2 | B5: 11/06/2026 | C5: 20:00 | D5: República de Corea | E5: República Checa | F5: 2 | G5: 1 | H5: =IF(AND(ISNUMBER(F5),ISNUMBER(G5)),"Finalizado","Pendiente") | I5: 1 | J5: Grupos | K5: -
A6: 3 | B6: 12/06/2026 | C6: 15:00 | D6: Canadá | E6: Bosnia y Herzegovina | F6: 1 | G6: 1 | H6: =IF(AND(ISNUMBER(F6),ISNUMBER(G6)),"Finalizado","Pendiente") | I6: 2 | J6: Grupos | K6: -
A7: 4 | B7: 12/06/2026 | C7: 18:00 | D7: Estados Unidos | E7: Paraguay | F7: 4 | G7: 1 | H7: =IF(AND(ISNUMBER(F7),ISNUMBER(G7)),"Finalizado","Pendiente") | I7: 4 | J7: Grupos | K7: -
A8: 5 | B8: 13/06/2026 | C8: 12:00 | D8: Catar | E8: Suiza | F8: 1 | G8: 1 | H8: =IF(AND(ISNUMBER(F8),ISNUMBER(G8)),"Finalizado","Pendiente") | I8: 2 | J8: Grupos | K8: -
A9: 6 | B9: 13/06/2026 | C9: 18:00 | D9: Brasil | E9: Marruecos | F9: 1 | G9: 1 | H9: =IF(AND(ISNUMBER(F9),ISNUMBER(G9)),"Finalizado","Pendiente") | I9: 3 | J9: Grupos | K9: -
A10: 7 | B10: 13/06/2026 | C10: 21:00 | D10: Haití | E10: Escocia | F10: 0 | G10: 1 | H10: =IF(AND(ISNUMBER(F10),ISNUMBER(G10)),"Finalizado","Pendiente") | I10: 3 | J10: Grupos | K10: -
A11: 8 | B11: 13/06/2026 | C11: 21:00 | D11: Australia | E11: Turquía | F11: 2 | G11: 0 | H11: =IF(AND(ISNUMBER(F11),ISNUMBER(G11)),"Finalizado","Pendiente") | I11: 4 | J11: Grupos | K11: -
A12: 9 | B12: 14/06/2026 | C12: 12:00 | D12: Alemania | E12: Curazao | F12: 7 | G12: 1 | H12: =IF(AND(ISNUMBER(F12),ISNUMBER(G12)),"Finalizado","Pendiente") | I12: 5 | J12: Grupos | K12: -
A13: 10 | B13: 14/06/2026 | C13: 15:00 | D13: Países Bajos | E13: Japón | F13: 2 | G13: 2 | H13: =IF(AND(ISNUMBER(F13),ISNUMBER(G13)),"Finalizado","Pendiente") | I13: 6 | J13: Grupos | K13: -
A14: 11 | B14: 14/06/2026 | C14: 19:00 | D14: Costa de Marfil | E14: Ecuador | F14: 1 | G14: 0 | H14: =IF(AND(ISNUMBER(F14),ISNUMBER(G14)),"Finalizado","Pendiente") | I14: 5 | J14: Grupos | K14: -
A15: 12 | B15: 14/06/2026 | C15: 20:00 | D15: Suecia | E15: Túnez | F15: 5 | G15: 1 | H15: =IF(AND(ISNUMBER(F15),ISNUMBER(G15)),"Finalizado","Pendiente") | I15: 6 | J15: Grupos | K15: -
... A103: 100 | B103: 11/07/2026 | C103: 20:00 | D103: Argentina | E103: Suiza | F103: 1 | G103: 1 | H103: =IF(AND(ISNUMBER(F103),ISNUMBER(G103)),"Finalizado","Pendiente") | I103: 15 | J103: Cuartos | K103: Local
A104: 101 | B104: 14/07/2026 | C104: 14:00 | D104: Francia | E104: Noruega | H104: =IF(AND(ISNUMBER(F104),ISNUMBER(G104)),"Finalizado","Pendiente") | I104: 16 | J104: Semifinal
A105: 102 | B105: 15/07/2026 | C105: 15:00 | D105: Bélgica | E105: Argentina | H105: =IF(AND(ISNUMBER(F105),ISNUMBER(G105)),"Finalizado","Pendiente") | I105: 16 | J105: Semifinal
A106: 103 | B106: 18/07/2026 | C106: 17:00 | D106: Perdedor Semifinal 1 | E106: Perdedor Semifinal 2 | H106: =IF(AND(ISNUMBER(F106),ISNUMBER(G106)),"Finalizado","Pendiente") | I106: 17 | J106: Tercer puesto
A107: 104 | B107: 19/07/2026 | C107: 15:00 | D107: Ganador Semifinal 1 | E107: Ganador Semifinal 2 | H107: =IF(AND(ISNUMBER(F107),ISNUMBER(G107)),"Finalizado","Pendiente") | I107: 17 | J107: Final

Sheet Pronosticos
A1: PRONÓSTICOS (consolidado)
A2: Vista automática de todos los pronósticos; no hace falta editar esta hoja.
A3: Partido | B3: Equipo local | C3: Equipo visitante | D3: Jugador | E3: Goles local | F3: Goles visitante | G3: Puntos | H3: Clasificado | I3: Fase | J3: Clasif OK
A4: 1 | B4: =IFERROR(INDEX(Partidos!$D$4:$D$107,MATCH($A4,Partidos!$A$4:$A$107,0)),"") | C4: =IFERROR(INDEX(Partidos!$E$4:$E$107,MATCH($A4,Partidos!$A$4:$A$107,0)),"") | D4: Álvaro | E4: =IFERROR(INDEX(Álvaro!F$4:F$107,MATCH($A4,Álvaro!$A$4:$A$107,0)),"") | F4: =IFERROR(INDEX(Álvaro!G$4:G$107,MATCH($A4,Álvaro!$A$4:$A$107,0)),"") | G4: =IFERROR(IF(INDEX(Partidos!$H$4:$H$107,MATCH($A4,Partidos!$A$4:$A$107,0))<>"Finalizado","",IF(OR(NOT(ISNUMBER($E4)),NOT(ISNUMBER($F4))),"",IF(INDEX(Partidos!$J$4:$J$107,MATCH($A4,Partidos!$A$4:$A$107,0))="Grupos",IF(AND($E4=INDEX(Partidos!$F$4:$F$107,MATCH($A4,Partidos!$A$4:$A$107,0)),$F4=INDEX(Partidos!$G$4:$G$107,MATCH($A4,Partidos!$A$4:$A$107,0))),Puntuacion!$B$4,IF(($E4-$F4)=(INDEX(Partidos!$F$4:$F$107,MATCH($A4,Partidos!$A$4:$A$107,0))-INDEX(Partidos!$G$4:$G$107,MATCH($A4,Partidos!$A$4:$A$107,0))),Puntuacion!$B$5,IF(OR(AND($E4>$F4,INDEX(Partidos!$F$4:$F$107,MATCH($A4,Partidos!$A$4:$A$107,0))>INDEX(Partidos!$G$4:$G$107,MATCH($A4,Partidos!$A$4:$A$107,0))),AND($E4=$F4,INDEX(Partidos!$F$4:$F$107,MATCH($A4,Partidos!$A$4:$A$107,0))=INDEX(Partidos!$G$4:$G$107,MATCH($A4,Partidos!$A$4:$A$107,0))),AND($E4<$F4,INDEX(Partidos!$F$4:$F$107,MATCH($A4,Partidos!$A$4:$A$107,0))<INDEX(Partidos!$G$4:$G$107,MATCH($A4,Partidos!$A$4:$A$107,0)))),Puntuacion!$B$6,0))),IF(AND($E4=INDEX(Partidos!$F$4:$F$107,MATCH($A4,Partidos!$A$4:$A$107,0)),$F4=INDEX(Partidos!$G$4:$G$107,MATCH($A4,Partidos!$A$4:$A$107,0))),Puntuacion!$B$9,IF(($E4-$F4)=(INDEX(Partidos!$F$4:$F$107,MATCH($A4,Partidos!$A$4:$A$107,0))-INDEX(Partidos!$G$4:$G$107,MATCH($A4,Partidos!$A$4:$A$107,0))),Puntuacion!$B$10,IF(AND($H4<>"",$H4=INDEX(Partidos!$K$4:$K$107,MATCH($A4,Partidos!$A$4:$A$107,0))),Puntuacion!$B$11,0)))))),"") | H4: =IFERROR(INDEX(Álvaro!H$4:H$107,MATCH($A4,Álvaro!$A$4:$A$107,0)),"") | I4: =IFERROR(INDEX(Partidos!$J$4:$J$107,MATCH($A4,Partidos!$A$4:$A$107,0)),"") | J4: =IF(AND(INDEX(Partidos!$J$4:$J$107,MATCH($A4,Partidos!$A$4:$A$107,0))<>"Grupos",INDEX(Partidos!$H$4:$H$107,MATCH($A4,Partidos!$A$4:$A$107,0))="Finalizado",$H4<>"",$H4=INDEX(Partidos!$K$4:$K$107,MATCH($A4,Partidos!$A$4:$A$107,0))),1,0)
A5: 1 | B5: =IFERROR(INDEX(Partidos!$D$4:$D$107,MATCH($A5,Partidos!$A$4:$A$107,0)),"") | C5: =IFERROR(INDEX(Partidos!$E$4:$E$107,MATCH($A5,Partidos!$A$4:$A$107,0)),"") | D5: Pepe | E5: =IFERROR(INDEX(Pepe!F$4:F$107,MATCH($A5,Pepe!$A$4:$A$107,0)),"") | F5: =IFERROR(INDEX(Pepe!G$4:G$107,MATCH($A5,Pepe!$A$4:$A$107,0)),"") | G5: =IFERROR(IF(INDEX(Partidos!$H$4:$H$107,MATCH($A5,Partidos!$A$4:$A$107,0))<>"Finalizado","",IF(OR(NOT(ISNUMBER($E5)),NOT(ISNUMBER($F5))),"",IF(INDEX(Partidos!$J$4:$J$107,MATCH($A5,Partidos!$A$4:$A$107,0))="Grupos",IF(AND($E5=INDEX(Partidos!$F$4:$F$107,MATCH($A5,Partidos!$A$4:$A$107,0)),$F5=INDEX(Partidos!$G$4:$G$107,MATCH($A5,Partidos!$A$4:$A$107,0))),Puntuacion!$B$4,IF(($E5-$F5)=(INDEX(Partidos!$F$4:$F$107,MATCH($A5,Partidos!$A$4:$A$107,0))-INDEX(Partidos!$G$4:$G$107,MATCH($A5,Partidos!$A$4:$A$107,0))),Puntuacion!$B$5,IF(OR(AND($E5>$F5,INDEX(Partidos!$F$4:$F$107,MATCH($A5,Partidos!$A$4:$A$107,0))>INDEX(Partidos!$G$4:$G$107,MATCH($A5,Partidos!$A$4:$A$107,0))),AND($E5=$F5,INDEX(Partidos!$F$4:$F$107,MATCH($A5,Partidos!$A$4:$A$107,0))=INDEX(Partidos!$G$4:$G$107,MATCH($A5,Partidos!$A$4:$A$107,0))),AND($E5<$F5,INDEX(Partidos!$F$4:$F$107,MATCH($A5,Partidos!$A$4:$A$107,0))<INDEX(Partidos!$G$4:$G$107,MATCH($A5,Partidos!$A$4:$A$107,0)))),Puntuacion!$B$6,0))),IF(AND($E5=INDEX(Partidos!$F$4:$F$107,MATCH($A5,Partidos!$A$4:$A$107,0)),$F5=INDEX(Partidos!$G$4:$G$107,MATCH($A5,Partidos!$A$4:$A$107,0))),Puntuacion!$B$9,IF(($E5-$F5)=(INDEX(Partidos!$F$4:$F$107,MATCH($A5,Partidos!$A$4:$A$107,0))-INDEX(Partidos!$G$4:$G$107,MATCH($A5,Partidos!$A$4:$A$107,0))),Puntuacion!$B$10,IF(AND($H5<>"",$H5=INDEX(Partidos!$K$4:$K$107,MATCH($A5,Partidos!$A$4:$A$107,0))),Puntuacion!$B$11,0)))))),"") | H5: =IFERROR(INDEX(Pepe!H$4:H$107,MATCH($A5,Pepe!$A$4:$A$107,0)),"") | I5: =IFERROR(INDEX(Partidos!$J$4:$J$107,MATCH($A5,Partidos!$A$4:$A$107,0)),"") | J5: =IF(AND(INDEX(Partidos!$J$4:$J$107,MATCH($A5,Partidos!$A$4:$A$107,0))<>"Grupos",INDEX(Partidos!$H$4:$H$107,MATCH($A5,Partidos!$A$4:$A$107,0))="Finalizado",$H5<>"",$H5=INDEX(Partidos!$K$4:$K$107,MATCH($A5,Partidos!$A$4:$A$107,0))),1,0)
A6: 1 | B6: =IFERROR(INDEX(Partidos!$D$4:$D$107,MATCH($A6,Partidos!$A$4:$A$107,0)),"") | C6: =IFERROR(INDEX(Partidos!$E$4:$E$107,MATCH($A6,Partidos!$A$4:$A$107,0)),"") | D6: Patri | E6: =IFERROR(INDEX(Patri!F$4:F$107,MATCH($A6,Patri!$A$4:$A$107,0)),"") | F6: =IFERROR(INDEX(Patri!G$4:G$107,MATCH($A6,Patri!$A$4:$A$107,0)),"") | G6: =IFERROR(IF(INDEX(Partidos!$H$4:$H$107,MATCH($A6,Partidos!$A$4:$A$107,0))<>"Finalizado","",IF(OR(NOT(ISNUMBER($E6)),NOT(ISNUMBER($F6))),"",IF(INDEX(Partidos!$J$4:$J$107,MATCH($A6,Partidos!$A$4:$A$107,0))="Grupos",IF(AND($E6=INDEX(Partidos!$F$4:$F$107,MATCH($A6,Partidos!$A$4:$A$107,0)),$F6=INDEX(Partidos!$G$4:$G$107,MATCH($A6,Partidos!$A$4:$A$107,0))),Puntuacion!$B$4,IF(($E6-$F6)=(INDEX(Partidos!$F$4:$F$107,MATCH($A6,Partidos!$A$4:$A$107,0))-INDEX(Partidos!$G$4:$G$107,MATCH($A6,Partidos!$A$4:$A$107,0))),Puntuacion!$B$5,IF(OR(AND($E6>$F6,INDEX(Partidos!$F$4:$F$107,MATCH($A6,Partidos!$A$4:$A$107,0))>INDEX(Partidos!$G$4:$G$107,MATCH($A6,Partidos!$A$4:$A$107,0))),AND($E6=$F6,INDEX(Partidos!$F$4:$F$107,MATCH($A6,Partidos!$A$4:$A$107,0))=INDEX(Partidos!$G$4:$G$107,MATCH($A6,Partidos!$A$4:$A$107,0))),AND($E6<$F6,INDEX(Partidos!$F$4:$F$107,MATCH($A6,Partidos!$A$4:$A$107,0))<INDEX(Partidos!$G$4:$G$107,MATCH($A6,Partidos!$A$4:$A$107,0)))),Puntuacion!$B$6,0))),IF(AND($E6=INDEX(Partidos!$F$4:$F$107,MATCH($A6,Partidos!$A$4:$A$107,0)),$F6=INDEX(Partidos!$G$4:$G$107,MATCH($A6,Partidos!$A$4:$A$107,0))),Puntuacion!$B$9,IF(($E6-$F6)=(INDEX(Partidos!$F$4:$F$107,MATCH($A6,Partidos!$A$4:$A$107,0))-INDEX(Partidos!$G$4:$G$107,MATCH($A6,Partidos!$A$4:$A$107,0))),Puntuacion!$B$10,IF(AND($H6<>"",$H6=INDEX(Partidos!$K$4:$K$107,MATCH($A6,Partidos!$A$4:$A$107,0))),Puntuacion!$B$11,0)))))),"") | H6: =IFERROR(INDEX(Patri!H$4:H$107,MATCH($A6,Patri!$A$4:$A$107,0)),"") | I6: =IFERROR(INDEX(Partidos!$J$4:$J$107,MATCH($A6,Partidos!$A$4:$A$107,0)),"") | J6: =IF(AND(INDEX(Partidos!$J$4:$J$107,MATCH($A6,Partidos!$A$4:$A$107,0))<>"Grupos",INDEX(Partidos!$H$4:$H$107,MATCH($A6,Partidos!$A$4:$A$107,0))="Finalizado",$H6<>"",$H6=INDEX(Partidos!$K$4:$K$107,MATCH($A6,Partidos!$A$4:$A$107,0))),1,0)
A7: 1 | B7: =IFERROR(INDEX(Partidos!$D$4:$D$107,MATCH($A7,Partidos!$A$4:$A$107,0)),"") | C7: =IFERROR(INDEX(Partidos!$E$4:$E$107,MATCH($A7,Partidos!$A$4:$A$107,0)),"") | D7: Kike | E7: =IFERROR(INDEX(Kike!F$4:F$107,MATCH($A7,Kike!$A$4:$A$107,0)),"") | F7: =IFERROR(INDEX(Kike!G$4:G$107,MATCH($A7,Kike!$A$4:$A$107,0)),"") | G7: =IFERROR(IF(INDEX(Partidos!$H$4:$H$107,MATCH($A7,Partidos!$A$4:$A$107,0))<>"Finalizado","",IF(OR(NOT(ISNUMBER($E7)),NOT(ISNUMBER($F7))),"",IF(INDEX(Partidos!$J$4:$J$107,MATCH($A7,Partidos!$A$4:$A$107,0))="Grupos",IF(AND($E7=INDEX(Partidos!$F$4:$F$107,MATCH($A7,Partidos!$A$4:$A$107,0)),$F7=INDEX(Partidos!$G$4:$G$107,MATCH($A7,Partidos!$A$4:$A$107,0))),Puntuacion!$B$4,IF(($E7-$F7)=(INDEX(Partidos!$F$4:$F$107,MATCH($A7,Partidos!$A$4:$A$107,0))-INDEX(Partidos!$G$4:$G$107,MATCH($A7,Partidos!$A$4:$A$107,0))),Puntuacion!$B$5,IF(OR(AND($E7>$F7,INDEX(Partidos!$F$4:$F$107,MATCH($A7,Partidos!$A$4:$A$107,0))>INDEX(Partidos!$G$4:$G$107,MATCH($A7,Partidos!$A$4:$A$107,0))),AND($E7=$F7,INDEX(Partidos!$F$4:$F$107,MATCH($A7,Partidos!$A$4:$A$107,0))=INDEX(Partidos!$G$4:$G$107,MATCH($A7,Partidos!$A$4:$A$107,0))),AND($E7<$F7,INDEX(Partidos!$F$4:$F$107,MATCH($A7,Partidos!$A$4:$A$107,0))<INDEX(Partidos!$G$4:$G$107,MATCH($A7,Partidos!$A$4:$A$107,0)))),Puntuacion!$B$6,0))),IF(AND($E7=INDEX(Partidos!$F$4:$F$107,MATCH($A7,Partidos!$A$4:$A$107,0)),$F7=INDEX(Partidos!$G$4:$G$107,MATCH($A7,Partidos!$A$4:$A$107,0))),Puntuacion!$B$9,IF(($E7-$F7)=(INDEX(Partidos!$F$4:$F$107,MATCH($A7,Partidos!$A$4:$A$107,0))-INDEX(Partidos!$G$4:$G$107,MATCH($A7,Partidos!$A$4:$A$107,0))),Puntuacion!$B$10,IF(AND($H7<>"",$H7=INDEX(Partidos!$K$4:$K$107,MATCH($A7,Partidos!$A$4:$A$107,0))),Puntuacion!$B$11,0)))))),"") | H7: =IFERROR(INDEX(Kike!H$4:H$107,MATCH($A7,Kike!$A$4:$A$107,0)),"") | I7: =IFERROR(INDEX(Partidos!$J$4:$J$107,MATCH($A7,Partidos!$A$4:$A$107,0)),"") | J7: =IF(AND(INDEX(Partidos!$J$4:$J$107,MATCH($A7,Partidos!$A$4:$A$107,0))<>"Grupos",INDEX(Partidos!$H$4:$H$107,MATCH($A7,Partidos!$A$4:$A$107,0))="Finalizado",$H7<>"",$H7=INDEX(Partidos!$K$4:$K$107,MATCH($A7,Partidos!$A$4:$A$107,0))),1,0)
A8: 1 | B8: =IFERROR(INDEX(Partidos!$D$4:$D$107,MATCH($A8,Partidos!$A$4:$A$107,0)),"") | C8: =IFERROR(INDEX(Partidos!$E$4:$E$107,MATCH($A8,Partidos!$A$4:$A$107,0)),"") | D8: Quintero | E8: =IFERROR(INDEX(Quintero!F$4:F$107,MATCH($A8,Quintero!$A$4:$A$107,0)),"") | F8: =IFERROR(INDEX(Quintero!G$4:G$107,MATCH($A8,Quintero!$A$4:$A$107,0)),"") | G8: =IFERROR(IF(INDEX(Partidos!$H$4:$H$107,MATCH($A8,Partidos!$A$4:$A$107,0))<>"Finalizado","",IF(OR(NOT(ISNUMBER($E8)),NOT(ISNUMBER($F8))),"",IF(INDEX(Partidos!$J$4:$J$107,MATCH($A8,Partidos!$A$4:$A$107,0))="Grupos",IF(AND($E8=INDEX(Partidos!$F$4:$F$107,MATCH($A8,Partidos!$A$4:$A$107,0)),$F8=INDEX(Partidos!$G$4:$G$107,MATCH($A8,Partidos!$A$4:$A$107,0))),Puntuacion!$B$4,IF(($E8-$F8)=(INDEX(Partidos!$F$4:$F$107,MATCH($A8,Partidos!$A$4:$A$107,0))-INDEX(Partidos!$G$4:$G$107,MATCH($A8,Partidos!$A$4:$A$107,0))),Puntuacion!$B$5,IF(OR(AND($E8>$F8,INDEX(Partidos!$F$4:$F$107,MATCH($A8,Partidos!$A$4:$A$107,0))>INDEX(Partidos!$G$4:$G$107,MATCH($A8,Partidos!$A$4:$A$107,0))),AND($E8=$F8,INDEX(Partidos!$F$4:$F$107,MATCH($A8,Partidos!$A$4:$A$107,0))=INDEX(Partidos!$G$4:$G$107,MATCH($A8,Partidos!$A$4:$A$107,0))),AND($E8<$F8,INDEX(Partidos!$F$4:$F$107,MATCH($A8,Partidos!$A$4:$A$107,0))<INDEX(Partidos!$G$4:$G$107,MATCH($A8,Partidos!$A$4:$A$107,0)))),Puntuacion!$B$6,0))),IF(AND($E8=INDEX(Partidos!$F$4:$F$107,MATCH($A8,Partidos!$A$4:$A$107,0)),$F8=INDEX(Partidos!$G$4:$G$107,MATCH($A8,Partidos!$A$4:$A$107,0))),Puntuacion!$B$9,IF(($E8-$F8)=(INDEX(Partidos!$F$4:$F$107,MATCH($A8,Partidos!$A$4:$A$107,0))-INDEX(Partidos!$G$4:$G$107,MATCH($A8,Partidos!$A$4:$A$107,0))),Puntuacion!$B$10,IF(AND($H8<>"",$H8=INDEX(Partidos!$K$4:$K$107,MATCH($A8,Partidos!$A$4:$A$107,0))),Puntuacion!$B$11,0)))))),"") | H8: =IFERROR(INDEX(Quintero!H$4:H$107,MATCH($A8,Quintero!$A$4:$A$107,0)),"") | I8: =IFERROR(INDEX(Partidos!$J$4:$J$107,MATCH($A8,Partidos!$A$4:$A$107,0)),"") | J8: =IF(AND(INDEX(Partidos!$J$4:$J$107,MATCH($A8,Partidos!$A$4:$A$107,0))<>"Grupos",INDEX(Partidos!$H$4:$H$107,MATCH($A8,Partidos!$A$4:$A$107,0))="Finalizado",$H8<>"",$H8=INDEX(Partidos!$K$4:$K$107,MATCH($A8,Partidos!$A$4:$A$107,0))),1,0)
A9: 1 | B9: =IFERROR(INDEX(Partidos!$D$4:$D$107,MATCH($A9,Partidos!$A$4:$A$107,0)),"") | C9: =IFERROR(INDEX(Partidos!$E$4:$E$107,MATCH($A9,Partidos!$A$4:$A$107,0)),"") | D9: Nacho | E9: =IFERROR(INDEX(Nacho!F$4:F$107,MATCH($A9,Nacho!$A$4:$A$107,0)),"") | F9: =IFERROR(INDEX(Nacho!G$4:G$107,MATCH($A9,Nacho!$A$4:$A$107,0)),"") | G9: =IFERROR(IF(INDEX(Partidos!$H$4:$H$107,MATCH($A9,Partidos!$A$4:$A$107,0))<>"Finalizado","",IF(OR(NOT(ISNUMBER($E9)),NOT(ISNUMBER($F9))),"",IF(INDEX(Partidos!$J$4:$J$107,MATCH($A9,Partidos!$A$4:$A$107,0))="Grupos",IF(AND($E9=INDEX(Partidos!$F$4:$F$107,MATCH($A9,Partidos!$A$4:$A$107,0)),$F9=INDEX(Partidos!$G$4:$G$107,MATCH($A9,Partidos!$A$4:$A$107,0))),Puntuacion!$B$4,IF(($E9-$F9)=(INDEX(Partidos!$F$4:$F$107,MATCH($A9,Partidos!$A$4:$A$107,0))-INDEX(Partidos!$G$4:$G$107,MATCH($A9,Partidos!$A$4:$A$107,0))),Puntuacion!$B$5,IF(OR(AND($E9>$F9,INDEX(Partidos!$F$4:$F$107,MATCH($A9,Partidos!$A$4:$A$107,0))>INDEX(Partidos!$G$4:$G$107,MATCH($A9,Partidos!$A$4:$A$107,0))),AND($E9=$F9,INDEX(Partidos!$F$4:$F$107,MATCH($A9,Partidos!$A$4:$A$107,0))=INDEX(Partidos!$G$4:$G$107,MATCH($A9,Partidos!$A$4:$A$107,0))),AND($E9<$F9,INDEX(Partidos!$F$4:$F$107,MATCH($A9,Partidos!$A$4:$A$107,0))<INDEX(Partidos!$G$4:$G$107,MATCH($A9,Partidos!$A$4:$A$107,0)))),Puntuacion!$B$6,0))),IF(AND($E9=INDEX(Partidos!$F$4:$F$107,MATCH($A9,Partidos!$A$4:$A$107,0)),$F9=INDEX(Partidos!$G$4:$G$107,MATCH($A9,Partidos!$A$4:$A$107,0))),Puntuacion!$B$9,IF(($E9-$F9)=(INDEX(Partidos!$F$4:$F$107,MATCH($A9,Partidos!$A$4:$A$107,0))-INDEX(Partidos!$G$4:$G$107,MATCH($A9,Partidos!$A$4:$A$107,0))),Puntuacion!$B$10,IF(AND($H9<>"",$H9=INDEX(Partidos!$K$4:$K$107,MATCH($A9,Partidos!$A$4:$A$107,0))),Puntuacion!$B$11,0)))))),"") | H9: =IFERROR(INDEX(Nacho!H$4:H$107,MATCH($A9,Nacho!$A$4:$A$107,0)),"") | I9: =IFERROR(INDEX(Partidos!$J$4:$J$107,MATCH($A9,Partidos!$A$4:$A$107,0)),"") | J9: =IF(AND(INDEX(Partidos!$J$4:$J$107,MATCH($A9,Partidos!$A$4:$A$107,0))<>"Grupos",INDEX(Partidos!$H$4:$H$107,MATCH($A9,Partidos!$A$4:$A$107,0))="Finalizado",$H9<>"",$H9=INDEX(Partidos!$K$4:$K$107,MATCH($A9,Partidos!$A$4:$A$107,0))),1,0)
A10: 1 | B10: =IFERROR(INDEX(Partidos!$D$4:$D$107,MATCH($A10,Partidos!$A$4:$A$107,0)),"") | C10: =IFERROR(INDEX(Partidos!$E$4:$E$107,MATCH($A10,Partidos!$A$4:$A$107,0)),"") | D10: Luis | E10: =IFERROR(INDEX(Luis!F$4:F$107,MATCH($A10,Luis!$A$4:$A$107,0)),"") | F10: =IFERROR(INDEX(Luis!G$4:G$107,MATCH($A10,Luis!$A$4:$A$107,0)),"") | G10: =IFERROR(IF(INDEX(Partidos!$H$4:$H$107,MATCH($A10,Partidos!$A$4:$A$107,0))<>"Finalizado","",IF(OR(NOT(ISNUMBER($E10)),NOT(ISNUMBER($F10))),"",IF(INDEX(Partidos!$J$4:$J$107,MATCH($A10,Partidos!$A$4:$A$107,0))="Grupos",IF(AND($E10=INDEX(Partidos!$F$4:$F$107,MATCH($A10,Partidos!$A$4:$A$107,0)),$F10=INDEX(Partidos!$G$4:$G$107,MATCH($A10,Partidos!$A$4:$A$107,0))),Puntuacion!$B$4,IF(($E10-$F10)=(INDEX(Partidos!$F$4:$F$107,MATCH($A10,Partidos!$A$4:$A$107,0))-INDEX(Partidos!$G$4:$G$107,MATCH($A10,Partidos!$A$4:$A$107,0))),Puntuacion!$B$5,IF(OR(AND($E10>$F10,INDEX(Partidos!$F$4:$F$107,MATCH($A10,Partidos!$A$4:$A$107,0))>INDEX(Partidos!$G$4:$G$107,MATCH($A10,Partidos!$A$4:$A$107,0))),AND($E10=$F10,INDEX(Partidos!$F$4:$F$107,MATCH($A10,Partidos!$A$4:$A$107,0))=INDEX(Partidos!$G$4:$G$107,MATCH($A10,Partidos!$A$4:$A$107,0))),AND($E10<$F10,INDEX(Partidos!$F$4:$F$107,MATCH($A10,Partidos!$A$4:$A$107,0))<INDEX(Partidos!$G$4:$G$107,MATCH($A10,Partidos!$A$4:$A$107,0)))),Puntuacion!$B$6,0))),IF(AND($E10=INDEX(Partidos!$F$4:$F$107,MATCH($A10,Partidos!$A$4:$A$107,0)),$F10=INDEX(Partidos!$G$4:$G$107,MATCH($A10,Partidos!$A$4:$A$107,0))),Puntuacion!$B$9,IF(($E10-$F10)=(INDEX(Partidos!$F$4:$F$107,MATCH($A10,Partidos!$A$4:$A$107,0))-INDEX(Partidos!$G$4:$G$107,MATCH($A10,Partidos!$A$4:$A$107,0))),Puntuacion!$B$10,IF(AND($H10<>"",$H10=INDEX(Partidos!$K$4:$K$107,MATCH($A10,Partidos!$A$4:$A$107,0))),Puntuacion!$B$11,0)))))),"") | H10: =IFERROR(INDEX(Luis!H$4:H$107,MATCH($A10,Luis!$A$4:$A$107,0)),"") | I10: =IFERROR(INDEX(Partidos!$J$4:$J$107,MATCH($A10,Partidos!$A$4:$A$107,0)),"") | J10: =IF(AND(INDEX(Partidos!$J$4:$J$107,MATCH($A10,Partidos!$A$4:$A$107,0))<>"Grupos",INDEX(Partidos!$H$4:$H$107,MATCH($A10,Partidos!$A$4:$A$107,0))="Finalizado",$H10<>"",$H10=INDEX(Partidos!$K$4:$K$107,MATCH($A10,Partidos!$A$4:$A$107,0))),1,0)
A11: 1 | B11: =IFERROR(INDEX(Partidos!$D$4:$D$107,MATCH($A11,Partidos!$A$4:$A$107,0)),"") | C11: =IFERROR(INDEX(Partidos!$E$4:$E$107,MATCH($A11,Partidos!$A$4:$A$107,0)),"") | D11: Felipe | E11: =IFERROR(INDEX(Felipe!F$4:F$107,MATCH($A11,Felipe!$A$4:$A$107,0)),"") | F11: =IFERROR(INDEX(Felipe!G$4:G$107,MATCH($A11,Felipe!$A$4:$A$107,0)),"") | G11: =IFERROR(IF(INDEX(Partidos!$H$4:$H$107,MATCH($A11,Partidos!$A$4:$A$107,0))<>"Finalizado","",IF(OR(NOT(ISNUMBER($E11)),NOT(ISNUMBER($F11))),"",IF(INDEX(Partidos!$J$4:$J$107,MATCH($A11,Partidos!$A$4:$A$107,0))="Grupos",IF(AND($E11=INDEX(Partidos!$F$4:$F$107,MATCH($A11,Partidos!$A$4:$A$107,0)),$F11=INDEX(Partidos!$G$4:$G$107,MATCH($A11,Partidos!$A$4:$A$107,0))),Puntuacion!$B$4,IF(($E11-$F11)=(INDEX(Partidos!$F$4:$F$107,MATCH($A11,Partidos!$A$4:$A$107,0))-INDEX(Partidos!$G$4:$G$107,MATCH($A11,Partidos!$A$4:$A$107,0))),Puntuacion!$B$5,IF(OR(AND($E11>$F11,INDEX(Partidos!$F$4:$F$107,MATCH($A11,Partidos!$A$4:$A$107,0))>INDEX(Partidos!$G$4:$G$107,MATCH($A11,Partidos!$A$4:$A$107,0))),AND($E11=$F11,INDEX(Partidos!$F$4:$F$107,MATCH($A11,Partidos!$A$4:$A$107,0))=INDEX(Partidos!$G$4:$G$107,MATCH($A11,Partidos!$A$4:$A$107,0))),AND($E11<$F11,INDEX(Partidos!$F$4:$F$107,MATCH($A11,Partidos!$A$4:$A$107,0))<INDEX(Partidos!$G$4:$G$107,MATCH($A11,Partidos!$A$4:$A$107,0)))),Puntuacion!$B$6,0))),IF(AND($E11=INDEX(Partidos!$F$4:$F$107,MATCH($A11,Partidos!$A$4:$A$107,0)),$F11=INDEX(Partidos!$G$4:$G$107,MATCH($A11,Partidos!$A$4:$A$107,0))),Puntuacion!$B$9,IF(($E11-$F11)=(INDEX(Partidos!$F$4:$F$107,MATCH($A11,Partidos!$A$4:$A$107,0))-INDEX(Partidos!$G$4:$G$107,MATCH($A11,Partidos!$A$4:$A$107,0))),Puntuacion!$B$10,IF(AND($H11<>"",$H11=INDEX(Partidos!$K$4:$K$107,MATCH($A11,Partidos!$A$4:$A$107,0))),Puntuacion!$B$11,0)))))),"") | H11: =IFERROR(INDEX(Felipe!H$4:H$107,MATCH($A11,Felipe!$A$4:$A$107,0)),"") | I11: =IFERROR(INDEX(Partidos!$J$4:$J$107,MATCH($A11,Partidos!$A$4:$A$107,0)),"") | J11: =IF(AND(INDEX(Partidos!$J$4:$J$107,MATCH($A11,Partidos!$A$4:$A$107,0))<>"Grupos",INDEX(Partidos!$H$4:$H$107,MATCH($A11,Partidos!$A$4:$A$107,0))="Finalizado",$H11<>"",$H11=INDEX(Partidos!$K$4:$K$107,MATCH($A11,Partidos!$A$4:$A$107,0))),1,0)
A12: 1 | B12: =IFERROR(INDEX(Partidos!$D$4:$D$107,MATCH($A12,Partidos!$A$4:$A$107,0)),"") | C12: =IFERROR(INDEX(Partidos!$E$4:$E$107,MATCH($A12,Partidos!$A$4:$A$107,0)),"") | D12: Simón | E12: =IFERROR(INDEX(Simón!F$4:F$107,MATCH($A12,Simón!$A$4:$A$107,0)),"") | F12: =IFERROR(INDEX(Simón!G$4:G$107,MATCH($A12,Simón!$A$4:$A$107,0)),"") | G12: =IFERROR(IF(INDEX(Partidos!$H$4:$H$107,MATCH($A12,Partidos!$A$4:$A$107,0))<>"Finalizado","",IF(OR(NOT(ISNUMBER($E12)),NOT(ISNUMBER($F12))),"",IF(INDEX(Partidos!$J$4:$J$107,MATCH($A12,Partidos!$A$4:$A$107,0))="Grupos",IF(AND($E12=INDEX(Partidos!$F$4:$F$107,MATCH($A12,Partidos!$A$4:$A$107,0)),$F12=INDEX(Partidos!$G$4:$G$107,MATCH($A12,Partidos!$A$4:$A$107,0))),Puntuacion!$B$4,IF(($E12-$F12)=(INDEX(Partidos!$F$4:$F$107,MATCH($A12,Partidos!$A$4:$A$107,0))-INDEX(Partidos!$G$4:$G$107,MATCH($A12,Partidos!$A$4:$A$107,0))),Puntuacion!$B$5,IF(OR(AND($E12>$F12,INDEX(Partidos!$F$4:$F$107,MATCH($A12,Partidos!$A$4:$A$107,0))>INDEX(Partidos!$G$4:$G$107,MATCH($A12,Partidos!$A$4:$A$107,0))),AND($E12=$F12,INDEX(Partidos!$F$4:$F$107,MATCH($A12,Partidos!$A$4:$A$107,0))=INDEX(Partidos!$G$4:$G$107,MATCH($A12,Partidos!$A$4:$A$107,0))),AND($E12<$F12,INDEX(Partidos!$F$4:$F$107,MATCH($A12,Partidos!$A$4:$A$107,0))<INDEX(Partidos!$G$4:$G$107,MATCH($A12,Partidos!$A$4:$A$107,0)))),Puntuacion!$B$6,0))),IF(AND($E12=INDEX(Partidos!$F$4:$F$107,MATCH($A12,Partidos!$A$4:$A$107,0)),$F12=INDEX(Partidos!$G$4:$G$107,MATCH($A12,Partidos!$A$4:$A$107,0))),Puntuacion!$B$9,IF(($E12-$F12)=(INDEX(Partidos!$F$4:$F$107,MATCH($A12,Partidos!$A$4:$A$107,0))-INDEX(Partidos!$G$4:$G$107,MATCH($A12,Partidos!$A$4:$A$107,0))),Puntuacion!$B$10,IF(AND($H12<>"",$H12=INDEX(Partidos!$K$4:$K$107,MATCH($A12,Partidos!$A$4:$A$107,0))),Puntuacion!$B$11,0)))))),"") | H12: =IFERROR(INDEX(Simón!H$4:H$107,MATCH($A12,Simón!$A$4:$A$107,0)),"") | I12: =IFERROR(INDEX(Partidos!$J$4:$J$107,MATCH($A12,Partidos!$A$4:$A$107,0)),"") | J12: =IF(AND(INDEX(Partidos!$J$4:$J$107,MATCH($A12,Partidos!$A$4:$A$107,0))<>"Grupos",INDEX(Partidos!$H$4:$H$107,MATCH($A12,Partidos!$A$4:$A$107,0))="Finalizado",$H12<>"",$H12=INDEX(Partidos!$K$4:$K$107,MATCH($A12,Partidos!$A$4:$A$107,0))),1,0)
A13: 1 | B13: =IFERROR(INDEX(Partidos!$D$4:$D$107,MATCH($A13,Partidos!$A$4:$A$107,0)),"") | C13: =IFERROR(INDEX(Partidos!$E$4:$E$107,MATCH($A13,Partidos!$A$4:$A$107,0)),"") | D13: Muni | E13: =IFERROR(INDEX(Muni!F$4:F$107,MATCH($A13,Muni!$A$4:$A$107,0)),"") | F13: =IFERROR(INDEX(Muni!G$4:G$107,MATCH($A13,Muni!$A$4:$A$107,0)),"") | G13: =IFERROR(IF(INDEX(Partidos!$H$4:$H$107,MATCH($A13,Partidos!$A$4:$A$107,0))<>"Finalizado","",IF(OR(NOT(ISNUMBER($E13)),NOT(ISNUMBER($F13))),"",IF(INDEX(Partidos!$J$4:$J$107,MATCH($A13,Partidos!$A$4:$A$107,0))="Grupos",IF(AND($E13=INDEX(Partidos!$F$4:$F$107,MATCH($A13,Partidos!$A$4:$A$107,0)),$F13=INDEX(Partidos!$G$4:$G$107,MATCH($A13,Partidos!$A$4:$A$107,0))),Puntuacion!$B$4,IF(($E13-$F13)=(INDEX(Partidos!$F$4:$F$107,MATCH($A13,Partidos!$A$4:$A$107,0))-INDEX(Partidos!$G$4:$G$107,MATCH($A13,Partidos!$A$4:$A$107,0))),Puntuacion!$B$5,IF(OR(AND($E13>$F13,INDEX(Partidos!$F$4:$F$107,MATCH($A13,Partidos!$A$4:$A$107,0))>INDEX(Partidos!$G$4:$G$107,MATCH($A13,Partidos!$A$4:$A$107,0))),AND($E13=$F13,INDEX(Partidos!$F$4:$F$107,MATCH($A13,Partidos!$A$4:$A$107,0))=INDEX(Partidos!$G$4:$G$107,MATCH($A13,Partidos!$A$4:$A$107,0))),AND($E13<$F13,INDEX(Partidos!$F$4:$F$107,MATCH($A13,Partidos!$A$4:$A$107,0))<INDEX(Partidos!$G$4:$G$107,MATCH($A13,Partidos!$A$4:$A$107,0)))),Puntuacion!$B$6,0))),IF(AND($E13=INDEX(Partidos!$F$4:$F$107,MATCH($A13,Partidos!$A$4:$A$107,0)),$F13=INDEX(Partidos!$G$4:$G$107,MATCH($A13,Partidos!$A$4:$A$107,0))),Puntuacion!$B$9,IF(($E13-$F13)=(INDEX(Partidos!$F$4:$F$107,MATCH($A13,Partidos!$A$4:$A$107,0))-INDEX(Partidos!$G$4:$G$107,MATCH($A13,Partidos!$A$4:$A$107,0))),Puntuacion!$B$10,IF(AND($H13<>"",$H13=INDEX(Partidos!$K$4:$K$107,MATCH($A13,Partidos!$A$4:$A$107,0))),Puntuacion!$B$11,0)))))),"") | H13: =IFERROR(INDEX(Muni!H$4:H$107,MATCH($A13,Muni!$A$4:$A$107,0)),"") | I13: =IFERROR(INDEX(Partidos!$J$4:$J$107,MATCH($A13,Partidos!$A$4:$A$107,0)),"") | J13: =IF(AND(INDEX(Partidos!$J$4:$J$107,MATCH($A13,Partidos!$A$4:$A$107,0))<>"Grupos",INDEX(Partidos!$H$4:$H$107,MATCH($A13,Partidos!$A$4:$A$107,0))="Finalizado",$H13<>"",$H13=INDEX(Partidos!$K$4:$K$107,MATCH($A13,Partidos!$A$4:$A$107,0))),1,0)
A14: 1 | B14: =IFERROR(INDEX(Partidos!$D$4:$D$107,MATCH($A14,Partidos!$A$4:$A$107,0)),"") | C14: =IFERROR(INDEX(Partidos!$E$4:$E$107,MATCH($A14,Partidos!$A$4:$A$107,0)),"") | D14: Fer | E14: =IFERROR(INDEX(Fer!F$4:F$107,MATCH($A14,Fer!$A$4:$A$107,0)),"") | F14: =IFERROR(INDEX(Fer!G$4:G$107,MATCH($A14,Fer!$A$4:$A$107,0)),"") | G14: =IFERROR(IF(INDEX(Partidos!$H$4:$H$107,MATCH($A14,Partidos!$A$4:$A$107,0))<>"Finalizado","",IF(OR(NOT(ISNUMBER($E14)),NOT(ISNUMBER($F14))),"",IF(INDEX(Partidos!$J$4:$J$107,MATCH($A14,Partidos!$A$4:$A$107,0))="Grupos",IF(AND($E14=INDEX(Partidos!$F$4:$F$107,MATCH($A14,Partidos!$A$4:$A$107,0)),$F14=INDEX(Partidos!$G$4:$G$107,MATCH($A14,Partidos!$A$4:$A$107,0))),Puntuacion!$B$4,IF(($E14-$F14)=(INDEX(Partidos!$F$4:$F$107,MATCH($A14,Partidos!$A$4:$A$107,0))-INDEX(Partidos!$G$4:$G$107,MATCH($A14,Partidos!$A$4:$A$107,0))),Puntuacion!$B$5,IF(OR(AND($E14>$F14,INDEX(Partidos!$F$4:$F$107,MATCH($A14,Partidos!$A$4:$A$107,0))>INDEX(Partidos!$G$4:$G$107,MATCH($A14,Partidos!$A$4:$A$107,0))),AND($E14=$F14,INDEX(Partidos!$F$4:$F$107,MATCH($A14,Partidos!$A$4:$A$107,0))=INDEX(Partidos!$G$4:$G$107,MATCH($A14,Partidos!$A$4:$A$107,0))),AND($E14<$F14,INDEX(Partidos!$F$4:$F$107,MATCH($A14,Partidos!$A$4:$A$107,0))<INDEX(Partidos!$G$4:$G$107,MATCH($A14,Partidos!$A$4:$A$107,0)))),Puntuacion!$B$6,0))),IF(AND($E14=INDEX(Partidos!$F$4:$F$107,MATCH($A14,Partidos!$A$4:$A$107,0)),$F14=INDEX(Partidos!$G$4:$G$107,MATCH($A14,Partidos!$A$4:$A$107,0))),Puntuacion!$B$9,IF(($E14-$F14)=(INDEX(Partidos!$F$4:$F$107,MATCH($A14,Partidos!$A$4:$A$107,0))-INDEX(Partidos!$G$4:$G$107,MATCH($A14,Partidos!$A$4:$A$107,0))),Puntuacion!$B$10,IF(AND($H14<>"",$H14=INDEX(Partidos!$K$4:$K$107,MATCH($A14,Partidos!$A$4:$A$107,0))),Puntuacion!$B$11,0)))))),"") | H14: =IFERROR(INDEX(Fer!H$4:H$107,MATCH($A14,Fer!$A$4:$A$107,0)),"") | I14: =IFERROR(INDEX(Partidos!$J$4:$J$107,MATCH($A14,Partidos!$A$4:$A$107,0)),"") | J14: =IF(AND(INDEX(Partidos!$J$4:$J$107,MATCH($A14,Partidos!$A$4:$A$107,0))<>"Grupos",INDEX(Partidos!$H$4:$H$107,MATCH($A14,Partidos!$A$4:$A$107,0))="Finalizado",$H14<>"",$H14=INDEX(Partidos!$K$4:$K$107,MATCH($A14,Partidos!$A$4:$A$107,0))),1,0)
A15: 2 | B15: =IFERROR(INDEX(Partidos!$D$4:$D$107,MATCH($A15,Partidos!$A$4:$A$107,0)),"") | C15: =IFERROR(INDEX(Partidos!$E$4:$E$107,MATCH($A15,Partidos!$A$4:$A$107,0)),"") | D15: Álvaro | E15: =IFERROR(INDEX(Álvaro!F$4:F$107,MATCH($A15,Álvaro!$A$4:$A$107,0)),"") | F15: =IFERROR(INDEX(Álvaro!G$4:G$107,MATCH($A15,Álvaro!$A$4:$A$107,0)),"") | G15: =IFERROR(IF(INDEX(Partidos!$H$4:$H$107,MATCH($A15,Partidos!$A$4:$A$107,0))<>"Finalizado","",IF(OR(NOT(ISNUMBER($E15)),NOT(ISNUMBER($F15))),"",IF(INDEX(Partidos!$J$4:$J$107,MATCH($A15,Partidos!$A$4:$A$107,0))="Grupos",IF(AND($E15=INDEX(Partidos!$F$4:$F$107,MATCH($A15,Partidos!$A$4:$A$107,0)),$F15=INDEX(Partidos!$G$4:$G$107,MATCH($A15,Partidos!$A$4:$A$107,0))),Puntuacion!$B$4,IF(($E15-$F15)=(INDEX(Partidos!$F$4:$F$107,MATCH($A15,Partidos!$A$4:$A$107,0))-INDEX(Partidos!$G$4:$G$107,MATCH($A15,Partidos!$A$4:$A$107,0))),Puntuacion!$B$5,IF(OR(AND($E15>$F15,INDEX(Partidos!$F$4:$F$107,MATCH($A15,Partidos!$A$4:$A$107,0))>INDEX(Partidos!$G$4:$G$107,MATCH($A15,Partidos!$A$4:$A$107,0))),AND($E15=$F15,INDEX(Partidos!$F$4:$F$107,MATCH($A15,Partidos!$A$4:$A$107,0))=INDEX(Partidos!$G$4:$G$107,MATCH($A15,Partidos!$A$4:$A$107,0))),AND($E15<$F15,INDEX(Partidos!$F$4:$F$107,MATCH($A15,Partidos!$A$4:$A$107,0))<INDEX(Partidos!$G$4:$G$107,MATCH($A15,Partidos!$A$4:$A$107,0)))),Puntuacion!$B$6,0))),IF(AND($E15=INDEX(Partidos!$F$4:$F$107,MATCH($A15,Partidos!$A$4:$A$107,0)),$F15=INDEX(Partidos!$G$4:$G$107,MATCH($A15,Partidos!$A$4:$A$107,0))),Puntuacion!$B$9,IF(($E15-$F15)=(INDEX(Partidos!$F$4:$F$107,MATCH($A15,Partidos!$A$4:$A$107,0))-INDEX(Partidos!$G$4:$G$107,MATCH($A15,Partidos!$A$4:$A$107,0))),Puntuacion!$B$10,IF(AND($H15<>"",$H15=INDEX(Partidos!$K$4:$K$107,MATCH($A15,Partidos!$A$4:$A$107,0))),Puntuacion!$B$11,0)))))),"") | H15: =IFERROR(INDEX(Álvaro!H$4:H$107,MATCH($A15,Álvaro!$A$4:$A$107,0)),"") | I15: =IFERROR(INDEX(Partidos!$J$4:$J$107,MATCH($A15,Partidos!$A$4:$A$107,0)),"") | J15: =IF(AND(INDEX(Partidos!$J$4:$J$107,MATCH($A15,Partidos!$A$4:$A$107,0))<>"Grupos",INDEX(Partidos!$H$4:$H$107,MATCH($A15,Partidos!$A$4:$A$107,0))="Finalizado",$H15<>"",$H15=INDEX(Partidos!$K$4:$K$107,MATCH($A15,Partidos!$A$4:$A$107,0))),1,0)
A16: 2 | B16: =IFERROR(INDEX(Partidos!$D$4:$D$107,MATCH($A16,Partidos!$A$4:$A$107,0)),"") | C16: =IFERROR(INDEX(Partidos!$E$4:$E$107,MATCH($A16,Partidos!$A$4:$A$107,0)),"") | D16: Pepe | E16: =IFERROR(INDEX(Pepe!F$4:F$107,MATCH($A16,Pepe!$A$4:$A$107,0)),"") | F16: =IFERROR(INDEX(Pepe!G$4:G$107,MATCH($A16,Pepe!$A$4:$A$107,0)),"") | G16: =IFERROR(IF(INDEX(Partidos!$H$4:$H$107,MATCH($A16,Partidos!$A$4:$A$107,0))<>"Finalizado","",IF(OR(NOT(ISNUMBER($E16)),NOT(ISNUMBER($F16))),"",IF(INDEX(Partidos!$J$4:$J$107,MATCH($A16,Partidos!$A$4:$A$107,0))="Grupos",IF(AND($E16=INDEX(Partidos!$F$4:$F$107,MATCH($A16,Partidos!$A$4:$A$107,0)),$F16=INDEX(Partidos!$G$4:$G$107,MATCH($A16,Partidos!$A$4:$A$107,0))),Puntuacion!$B$4,IF(($E16-$F16)=(INDEX(Partidos!$F$4:$F$107,MATCH($A16,Partidos!$A$4:$A$107,0))-INDEX(Partidos!$G$4:$G$107,MATCH($A16,Partidos!$A$4:$A$107,0))),Puntuacion!$B$5,IF(OR(AND($E16>$F16,INDEX(Partidos!$F$4:$F$107,MATCH($A16,Partidos!$A$4:$A$107,0))>INDEX(Partidos!$G$4:$G$107,MATCH($A16,Partidos!$A$4:$A$107,0))),AND($E16=$F16,INDEX(Partidos!$F$4:$F$107,MATCH($A16,Partidos!$A$4:$A$107,0))=INDEX(Partidos!$G$4:$G$107,MATCH($A16,Partidos!$A$4:$A$107,0))),AND($E16<$F16,INDEX(Partidos!$F$4:$F$107,MATCH($A16,Partidos!$A$4:$A$107,0))<INDEX(Partidos!$G$4:$G$107,MATCH($A16,Partidos!$A$4:$A$107,0)))),Puntuacion!$B$6,0))),IF(AND($E16=INDEX(Partidos!$F$4:$F$107,MATCH($A16,Partidos!$A$4:$A$107,0)),$F16=INDEX(Partidos!$G$4:$G$107,MATCH($A16,Partidos!$A$4:$A$107,0))),Puntuacion!$B$9,IF(($E16-$F16)=(INDEX(Partidos!$F$4:$F$107,MATCH($A16,Partidos!$A$4:$A$107,0))-INDEX(Partidos!$G$4:$G$107,MATCH($A16,Partidos!$A$4:$A$107,0))),Puntuacion!$B$10,IF(AND($H16<>"",$H16=INDEX(Partidos!$K$4:$K$107,MATCH($A16,Partidos!$A$4:$A$107,0))),Puntuacion!$B$11,0)))))),"") | H16: =IFERROR(INDEX(Pepe!H$4:H$107,MATCH($A16,Pepe!$A$4:$A$107,0)),"") | I16: =IFERROR(INDEX(Partidos!$J$4:$J$107,MATCH($A16,Partidos!$A$4:$A$107,0)),"") | J16: =IF(AND(INDEX(Partidos!$J$4:$J$107,MATCH($A16,Partidos!$A$4:$A$107,0))<>"Grupos",INDEX(Partidos!$H$4:$H$107,MATCH($A16,Partidos!$A$4:$A$107,0))="Finalizado",$H16<>"",$H16=INDEX(Partidos!$K$4:$K$107,MATCH($A16,Partidos!$A$4:$A$107,0))),1,0)
A17: 2 | B17: =IFERROR(INDEX(Partidos!$D$4:$D$107,MATCH($A17,Partidos!$A$4:$A$107,0)),"") | C17: =IFERROR(INDEX(Partidos!$E$4:$E$107,MATCH($A17,Partidos!$A$4:$A$107,0)),"") | D17: Patri | E17: =IFERROR(INDEX(Patri!F$4:F$107,MATCH($A17,Patri!$A$4:$A$107,0)),"") | F17: =IFERROR(INDEX(Patri!G$4:G$107,MATCH($A17,Patri!$A$4:$A$107,0)),"") | G17: =IFERROR(IF(INDEX(Partidos!$H$4:$H$107,MATCH($A17,Partidos!$A$4:$A$107,0))<>"Finalizado","",IF(OR(NOT(ISNUMBER($E17)),NOT(ISNUMBER($F17))),"",IF(INDEX(Partidos!$J$4:$J$107,MATCH($A17,Partidos!$A$4:$A$107,0))="Grupos",IF(AND($E17=INDEX(Partidos!$F$4:$F$107,MATCH($A17,Partidos!$A$4:$A$107,0)),$F17=INDEX(Partidos!$G$4:$G$107,MATCH($A17,Partidos!$A$4:$A$107,0))),Puntuacion!$B$4,IF(($E17-$F17)=(INDEX(Partidos!$F$4:$F$107,MATCH($A17,Partidos!$A$4:$A$107,0))-INDEX(Partidos!$G$4:$G$107,MATCH($A17,Partidos!$A$4:$A$107,0))),Puntuacion!$B$5,IF(OR(AND($E17>$F17,INDEX(Partidos!$F$4:$F$107,MATCH($A17,Partidos!$A$4:$A$107,0))>INDEX(Partidos!$G$4:$G$107,MATCH($A17,Partidos!$A$4:$A$107,0))),AND($E17=$F17,INDEX(Partidos!$F$4:$F$107,MATCH($A17,Partidos!$A$4:$A$107,0))=INDEX(Partidos!$G$4:$G$107,MATCH($A17,Partidos!$A$4:$A$107,0))),AND($E17<$F17,INDEX(Partidos!$F$4:$F$107,MATCH($A17,Partidos!$A$4:$A$107,0))<INDEX(Partidos!$G$4:$G$107,MATCH($A17,Partidos!$A$4:$A$107,0)))),Puntuacion!$B$6,0))),IF(AND($E17=INDEX(Partidos!$F$4:$F$107,MATCH($A17,Partidos!$A$4:$A$107,0)),$F17=INDEX(Partidos!$G$4:$G$107,MATCH($A17,Partidos!$A$4:$A$107,0))),Puntuacion!$B$9,IF(($E17-$F17)=(INDEX(Partidos!$F$4:$F$107,MATCH($A17,Partidos!$A$4:$A$107,0))-INDEX(Partidos!$G$4:$G$107,MATCH($A17,Partidos!$A$4:$A$107,0))),Puntuacion!$B$10,IF(AND($H17<>"",$H17=INDEX(Partidos!$K$4:$K$107,MATCH($A17,Partidos!$A$4:$A$107,0))),Puntuacion!$B$11,0)))))),"") | H17: =IFERROR(INDEX(Patri!H$4:H$107,MATCH($A17,Patri!$A$4:$A$107,0)),"") | I17: =IFERROR(INDEX(Partidos!$J$4:$J$107,MATCH($A17,Partidos!$A$4:$A$107,0)),"") | J17: =IF(AND(INDEX(Partidos!$J$4:$J$107,MATCH($A17,Partidos!$A$4:$A$107,0))<>"Grupos",INDEX(Partidos!$H$4:$H$107,MATCH($A17,Partidos!$A$4:$A$107,0))="Finalizado",$H17<>"",$H17=INDEX(Partidos!$K$4:$K$107,MATCH($A17,Partidos!$A$4:$A$107,0))),1,0)
A18: 2 | B18: =IFERROR(INDEX(Partidos!$D$4:$D$107,MATCH($A18,Partidos!$A$4:$A$107,0)),"") | C18: =IFERROR(INDEX(Partidos!$E$4:$E$107,MATCH($A18,Partidos!$A$4:$A$107,0)),"") | D18: Kike | E18: =IFERROR(INDEX(Kike!F$4:F$107,MATCH($A18,Kike!$A$4:$A$107,0)),"") | F18: =IFERROR(INDEX(Kike!G$4:G$107,MATCH($A18,Kike!$A$4:$A$107,0)),"") | G18: =IFERROR(IF(INDEX(Partidos!$H$4:$H$107,MATCH($A18,Partidos!$A$4:$A$107,0))<>"Finalizado","",IF(OR(NOT(ISNUMBER($E18)),NOT(ISNUMBER($F18))),"",IF(INDEX(Partidos!$J$4:$J$107,MATCH($A18,Partidos!$A$4:$A$107,0))="Grupos",IF(AND($E18=INDEX(Partidos!$F$4:$F$107,MATCH($A18,Partidos!$A$4:$A$107,0)),$F18=INDEX(Partidos!$G$4:$G$107,MATCH($A18,Partidos!$A$4:$A$107,0))),Puntuacion!$B$4,IF(($E18-$F18)=(INDEX(Partidos!$F$4:$F$107,MATCH($A18,Partidos!$A$4:$A$107,0))-INDEX(Partidos!$G$4:$G$107,MATCH($A18,Partidos!$A$4:$A$107,0))),Puntuacion!$B$5,IF(OR(AND($E18>$F18,INDEX(Partidos!$F$4:$F$107,MATCH($A18,Partidos!$A$4:$A$107,0))>INDEX(Partidos!$G$4:$G$107,MATCH($A18,Partidos!$A$4:$A$107,0))),AND($E18=$F18,INDEX(Partidos!$F$4:$F$107,MATCH($A18,Partidos!$A$4:$A$107,0))=INDEX(Partidos!$G$4:$G$107,MATCH($A18,Partidos!$A$4:$A$107,0))),AND($E18<$F18,INDEX(Partidos!$F$4:$F$107,MATCH($A18,Partidos!$A$4:$A$107,0))<INDEX(Partidos!$G$4:$G$107,MATCH($A18,Partidos!$A$4:$A$107,0)))),Puntuacion!$B$6,0))),IF(AND($E18=INDEX(Partidos!$F$4:$F$107,MATCH($A18,Partidos!$A$4:$A$107,0)),$F18=INDEX(Partidos!$G$4:$G$107,MATCH($A18,Partidos!$A$4:$A$107,0))),Puntuacion!$B$9,IF(($E18-$F18)=(INDEX(Partidos!$F$4:$F$107,MATCH($A18,Partidos!$A$4:$A$107,0))-INDEX(Partidos!$G$4:$G$107,MATCH($A18,Partidos!$A$4:$A$107,0))),Puntuacion!$B$10,IF(AND($H18<>"",$H18=INDEX(Partidos!$K$4:$K$107,MATCH($A18,Partidos!$A$4:$A$107,0))),Puntuacion!$B$11,0)))))),"") | H18: =IFERROR(INDEX(Kike!H$4:H$107,MATCH($A18,Kike!$A$4:$A$107,0)),"") | I18: =IFERROR(INDEX(Partidos!$J$4:$J$107,MATCH($A18,Partidos!$A$4:$A$107,0)),"") | J18: =IF(AND(INDEX(Partidos!$J$4:$J$107,MATCH($A18,Partidos!$A$4:$A$107,0))<>"Grupos",INDEX(Partidos!$H$4:$H$107,MATCH($A18,Partidos!$A$4:$A$107,0))="Finalizado",$H18<>"",$H18=INDEX(Partidos!$K$4:$K$107,MATCH($A18,Partidos!$A$4:$A$107,0))),1,0)
A19: 2 | B19: =IFERROR(INDEX(Partidos!$D$4:$D$107,MATCH($A19,Partidos!$A$4:$A$107,0)),"") | C19: =IFERROR(INDEX(Partidos!$E$4:$E$107,MATCH($A19,Partidos!$A$4:$A$107,0)),"") | D19: Quintero | E19: =IFERROR(INDEX(Quintero!F$4:F$107,MATCH($A19,Quintero!$A$4:$A$107,0)),"") | F19: =IFERROR(INDEX(Quintero!G$4:G$107,MATCH($A19,Quintero!$A$4:$A$107,0)),"") | G19: =IFERROR(IF(INDEX(Partidos!$H$4:$H$107,MATCH($A19,Partidos!$A$4:$A$107,0))<>"Finalizado","",IF(OR(NOT(ISNUMBER($E19)),NOT(ISNUMBER($F19))),"",IF(INDEX(Partidos!$J$4:$J$107,MATCH($A19,Partidos!$A$4:$A$107,0))="Grupos",IF(AND($E19=INDEX(Partidos!$F$4:$F$107,MATCH($A19,Partidos!$A$4:$A$107,0)),$F19=INDEX(Partidos!$G$4:$G$107,MATCH($A19,Partidos!$A$4:$A$107,0))),Puntuacion!$B$4,IF(($E19-$F19)=(INDEX(Partidos!$F$4:$F$107,MATCH($A19,Partidos!$A$4:$A$107,0))-INDEX(Partidos!$G$4:$G$107,MATCH($A19,Partidos!$A$4:$A$107,0))),Puntuacion!$B$5,IF(OR(AND($E19>$F19,INDEX(Partidos!$F$4:$F$107,MATCH($A19,Partidos!$A$4:$A$107,0))>INDEX(Partidos!$G$4:$G$107,MATCH($A19,Partidos!$A$4:$A$107,0))),AND($E19=$F19,INDEX(Partidos!$F$4:$F$107,MATCH($A19,Partidos!$A$4:$A$107,0))=INDEX(Partidos!$G$4:$G$107,MATCH($A19,Partidos!$A$4:$A$107,0))),AND($E19<$F19,INDEX(Partidos!$F$4:$F$107,MATCH($A19,Partidos!$A$4:$A$107,0))<INDEX(Partidos!$G$4:$G$107,MATCH($A19,Partidos!$A$4:$A$107,0)))),Puntuacion!$B$6,0))),IF(AND($E19=INDEX(Partidos!$F$4:$F$107,MATCH($A19,Partidos!$A$4:$A$107,0)),$F19=INDEX(Partidos!$G$4:$G$107,MATCH($A19,Partidos!$A$4:$A$107,0))),Puntuacion!$B$9,IF(($E19-$F19)=(INDEX(Partidos!$F$4:$F$107,MATCH($A19,Partidos!$A$4:$A$107,0))-INDEX(Partidos!$G$4:$G$107,MATCH($A19,Partidos!$A$4:$A$107,0))),Puntuacion!$B$10,IF(AND($H19<>"",$H19=INDEX(Partidos!$K$4:$K$107,MATCH($A19,Partidos!$A$4:$A$107,0))),Puntuacion!$B$11,0)))))),"") | H19: =IFERROR(INDEX(Quintero!H$4:H$107,MATCH($A19,Quintero!$A$4:$A$107,0)),"") | I19: =IFERROR(INDEX(Partidos!$J$4:$J$107,MATCH($A19,Partidos!$A$4:$A$107,0)),"") | J19: =IF(AND(INDEX(Partidos!$J$4:$J$107,MATCH($A19,Partidos!$A$4:$A$107,0))<>"Grupos",INDEX(Partidos!$H$4:$H$107,MATCH($A19,Partidos!$A$4:$A$107,0))="Finalizado",$H19<>"",$H19=INDEX(Partidos!$K$4:$K$107,MATCH($A19,Partidos!$A$4:$A$107,0))),1,0)
A20: 2 | B20: =IFERROR(INDEX(Partidos!$D$4:$D$107,MATCH($A20,Partidos!$A$4:$A$107,0)),"") | C20: =IFERROR(INDEX(Partidos!$E$4:$E$107,MATCH($A20,Partidos!$A$4:$A$107,0)),"") | D20: Nacho | E20: =IFERROR(INDEX(Nacho!F$4:F$107,MATCH($A20,Nacho!$A$4:$A$107,0)),"") | F20: =IFERROR(INDEX(Nacho!G$4:G$107,MATCH($A20,Nacho!$A$4:$A$107,0)),"") | G20: =IFERROR(IF(INDEX(Partidos!$H$4:$H$107,MATCH($A20,Partidos!$A$4:$A$107,0))<>"Finalizado","",IF(OR(NOT(ISNUMBER($E20)),NOT(ISNUMBER($F20))),"",IF(INDEX(Partidos!$J$4:$J$107,MATCH($A20,Partidos!$A$4:$A$107,0))="Grupos",IF(AND($E20=INDEX(Partidos!$F$4:$F$107,MATCH($A20,Partidos!$A$4:$A$107,0)),$F20=INDEX(Partidos!$G$4:$G$107,MATCH($A20,Partidos!$A$4:$A$107,0))),Puntuacion!$B$4,IF(($E20-$F20)=(INDEX(Partidos!$F$4:$F$107,MATCH($A20,Partidos!$A$4:$A$107,0))-INDEX(Partidos!$G$4:$G$107,MATCH($A20,Partidos!$A$4:$A$107,0))),Puntuacion!$B$5,IF(OR(AND($E20>$F20,INDEX(Partidos!$F$4:$F$107,MATCH($A20,Partidos!$A$4:$A$107,0))>INDEX(Partidos!$G$4:$G$107,MATCH($A20,Partidos!$A$4:$A$107,0))),AND($E20=$F20,INDEX(Partidos!$F$4:$F$107,MATCH($A20,Partidos!$A$4:$A$107,0))=INDEX(Partidos!$G$4:$G$107,MATCH($A20,Partidos!$A$4:$A$107,0))),AND($E20<$F20,INDEX(Partidos!$F$4:$F$107,MATCH($A20,Partidos!$A$4:$A$107,0))<INDEX(Partidos!$G$4:$G$107,MATCH($A20,Partidos!$A$4:$A$107,0)))),Puntuacion!$B$6,0))),IF(AND($E20=INDEX(Partidos!$F$4:$F$107,MATCH($A20,Partidos!$A$4:$A$107,0)),$F20=INDEX(Partidos!$G$4:$G$107,MATCH($A20,Partidos!$A$4:$A$107,0))),Puntuacion!$B$9,IF(($E20-$F20)=(INDEX(Partidos!$F$4:$F$107,MATCH($A20,Partidos!$A$4:$A$107,0))-INDEX(Partidos!$G$4:$G$107,MATCH($A20,Partidos!$A$4:$A$107,0))),Puntuacion!$B$10,IF(AND($H20<>"",$H20=INDEX(Partidos!$K$4:$K$107,MATCH($A20,Partidos!$A$4:$A$107,0))),Puntuacion!$B$11,0)))))),"") | H20: =IFERROR(INDEX(Nacho!H$4:H$107,MATCH($A20,Nacho!$A$4:$A$107,0)),"") | I20: =IFERROR(INDEX(Partidos!$J$4:$J$107,MATCH($A20,Partidos!$A$4:$A$107,0)),"") | J20: =IF(AND(INDEX(Partidos!$J$4:$J$107,MATCH($A20,Partidos!$A$4:$A$107,0))<>"Grupos",INDEX(Partidos!$H$4:$H$107,MATCH($A20,Partidos!$A$4:$A$107,0))="Finalizado",$H20<>"",$H20=INDEX(Partidos!$K$4:$K$107,MATCH($A20,Partidos!$A$4:$A$107,0))),1,0)
A21: 2 | B21: =IFERROR(INDEX(Partidos!$D$4:$D$107,MATCH($A21,Partidos!$A$4:$A$107,0)),"") | C21: =IFERROR(INDEX(Partidos!$E$4:$E$107,MATCH($A21,Partidos!$A$4:$A$107,0)),"") | D21: Luis | E21: =IFERROR(INDEX(Luis!F$4:F$107,MATCH($A21,Luis!$A$4:$A$107,0)),"") | F21: =IFERROR(INDEX(Luis!G$4:G$107,MATCH($A21,Luis!$A$4:$A$107,0)),"") | G21: =IFERROR(IF(INDEX(Partidos!$H$4:$H$107,MATCH($A21,Partidos!$A$4:$A$107,0))<>"Finalizado","",IF(OR(NOT(ISNUMBER($E21)),NOT(ISNUMBER($F21))),"",IF(INDEX(Partidos!$J$4:$J$107,MATCH($A21,Partidos!$A$4:$A$107,0))="Grupos",IF(AND($E21=INDEX(Partidos!$F$4:$F$107,MATCH($A21,Partidos!$A$4:$A$107,0)),$F21=INDEX(Partidos!$G$4:$G$107,MATCH($A21,Partidos!$A$4:$A$107,0))),Puntuacion!$B$4,IF(($E21-$F21)=(INDEX(Partidos!$F$4:$F$107,MATCH($A21,Partidos!$A$4:$A$107,0))-INDEX(Partidos!$G$4:$G$107,MATCH($A21,Partidos!$A$4:$A$107,0))),Puntuacion!$B$5,IF(OR(AND($E21>$F21,INDEX(Partidos!$F$4:$F$107,MATCH($A21,Partidos!$A$4:$A$107,0))>INDEX(Partidos!$G$4:$G$107,MATCH($A21,Partidos!$A$4:$A$107,0))),AND($E21=$F21,INDEX(Partidos!$F$4:$F$107,MATCH($A21,Partidos!$A$4:$A$107,0))=INDEX(Partidos!$G$4:$G$107,MATCH($A21,Partidos!$A$4:$A$107,0))),AND($E21<$F21,INDEX(Partidos!$F$4:$F$107,MATCH($A21,Partidos!$A$4:$A$107,0))<INDEX(Partidos!$G$4:$G$107,MATCH($A21,Partidos!$A$4:$A$107,0)))),Puntuacion!$B$6,0))),IF(AND($E21=INDEX(Partidos!$F$4:$F$107,MATCH($A21,Partidos!$A$4:$A$107,0)),$F21=INDEX(Partidos!$G$4:$G$107,MATCH($A21,Partidos!$A$4:$A$107,0))),Puntuacion!$B$9,IF(($E21-$F21)=(INDEX(Partidos!$F$4:$F$107,MATCH($A21,Partidos!$A$4:$A$107,0))-INDEX(Partidos!$G$4:$G$107,MATCH($A21,Partidos!$A$4:$A$107,0))),Puntuacion!$B$10,IF(AND($H21<>"",$H21=INDEX(Partidos!$K$4:$K$107,MATCH($A21,Partidos!$A$4:$A$107,0))),Puntuacion!$B$11,0)))))),"") | H21: =IFERROR(INDEX(Luis!H$4:H$107,MATCH($A21,Luis!$A$4:$A$107,0)),"") | I21: =IFERROR(INDEX(Partidos!$J$4:$J$107,MATCH($A21,Partidos!$A$4:$A$107,0)),"") | J21: =IF(AND(INDEX(Partidos!$J$4:$J$107,MATCH($A21,Partidos!$A$4:$A$107,0))<>"Grupos",INDEX(Partidos!$H$4:$H$107,MATCH($A21,Partidos!$A$4:$A$107,0))="Finalizado",$H21<>"",$H21=INDEX(Partidos!$K$4:$K$107,MATCH($A21,Partidos!$A$4:$A$107,0))),1,0)
A22: 2 | B22: =IFERROR(INDEX(Partidos!$D$4:$D$107,MATCH($A22,Partidos!$A$4:$A$107,0)),"") | C22: =IFERROR(INDEX(Partidos!$E$4:$E$107,MATCH($A22,Partidos!$A$4:$A$107,0)),"") | D22: Felipe | E22: =IFERROR(INDEX(Felipe!F$4:F$107,MATCH($A22,Felipe!$A$4:$A$107,0)),"") | F22: =IFERROR(INDEX(Felipe!G$4:G$107,MATCH($A22,Felipe!$A$4:$A$107,0)),"") | G22: =IFERROR(IF(INDEX(Partidos!$H$4:$H$107,MATCH($A22,Partidos!$A$4:$A$107,0))<>"Finalizado","",IF(OR(NOT(ISNUMBER($E22)),NOT(ISNUMBER($F22))),"",IF(INDEX(Partidos!$J$4:$J$107,MATCH($A22,Partidos!$A$4:$A$107,0))="Grupos",IF(AND($E22=INDEX(Partidos!$F$4:$F$107,MATCH($A22,Partidos!$A$4:$A$107,0)),$F22=INDEX(Partidos!$G$4:$G$107,MATCH($A22,Partidos!$A$4:$A$107,0))),Puntuacion!$B$4,IF(($E22-$F22)=(INDEX(Partidos!$F$4:$F$107,MATCH($A22,Partidos!$A$4:$A$107,0))-INDEX(Partidos!$G$4:$G$107,MATCH($A22,Partidos!$A$4:$A$107,0))),Puntuacion!$B$5,IF(OR(AND($E22>$F22,INDEX(Partidos!$F$4:$F$107,MATCH($A22,Partidos!$A$4:$A$107,0))>INDEX(Partidos!$G$4:$G$107,MATCH($A22,Partidos!$A$4:$A$107,0))),AND($E22=$F22,INDEX(Partidos!$F$4:$F$107,MATCH($A22,Partidos!$A$4:$A$107,0))=INDEX(Partidos!$G$4:$G$107,MATCH($A22,Partidos!$A$4:$A$107,0))),AND($E22<$F22,INDEX(Partidos!$F$4:$F$107,MATCH($A22,Partidos!$A$4:$A$107,0))<INDEX(Partidos!$G$4:$G$107,MATCH($A22,Partidos!$A$4:$A$107,0)))),Puntuacion!$B$6,0))),IF(AND($E22=INDEX(Partidos!$F$4:$F$107,MATCH($A22,Partidos!$A$4:$A$107,0)),$F22=INDEX(Partidos!$G$4:$G$107,MATCH($A22,Partidos!$A$4:$A$107,0))),Puntuacion!$B$9,IF(($E22-$F22)=(INDEX(Partidos!$F$4:$F$107,MATCH($A22,Partidos!$A$4:$A$107,0))-INDEX(Partidos!$G$4:$G$107,MATCH($A22,Partidos!$A$4:$A$107,0))),Puntuacion!$B$10,IF(AND($H22<>"",$H22=INDEX(Partidos!$K$4:$K$107,MATCH($A22,Partidos!$A$4:$A$107,0))),Puntuacion!$B$11,0)))))),"") | H22: =IFERROR(INDEX(Felipe!H$4:H$107,MATCH($A22,Felipe!$A$4:$A$107,0)),"") | I22: =IFERROR(INDEX(Partidos!$J$4:$J$107,MATCH($A22,Partidos!$A$4:$A$107,0)),"") | J22: =IF(AND(INDEX(Partidos!$J$4:$J$107,MATCH($A22,Partidos!$A$4:$A$107,0))<>"Grupos",INDEX(Partidos!$H$4:$H$107,MATCH($A22,Partidos!$A$4:$A$107,0))="Finalizado",$H22<>"",$H22=INDEX(Partidos!$K$4:$K$107,MATCH($A22,Partidos!$A$4:$A$107,0))),1,0)
A23: 2 | B23: =IFERROR(INDEX(Partidos!$D$4:$D$107,MATCH($A23,Partidos!$A$4:$A$107,0)),"") | C23: =IFERROR(INDEX(Partidos!$E$4:$E$107,MATCH($A23,Partidos!$A$4:$A$107,0)),"") | D23: Simón | E23: =IFERROR(INDEX(Simón!F$4:F$107,MATCH($A23,Simón!$A$4:$A$107,0)),"") | F23: =IFERROR(INDEX(Simón!G$4:G$107,MATCH($A23,Simón!$A$4:$A$107,0)),"") | G23: =IFERROR(IF(INDEX(Partidos!$H$4:$H$107,MATCH($A23,Partidos!$A$4:$A$107,0))<>"Finalizado","",IF(OR(NOT(ISNUMBER($E23)),NOT(ISNUMBER($F23))),"",IF(INDEX(Partidos!$J$4:$J$107,MATCH($A23,Partidos!$A$4:$A$107,0))="Grupos",IF(AND($E23=INDEX(Partidos!$F$4:$F$107,MATCH($A23,Partidos!$A$4:$A$107,0)),$F23=INDEX(Partidos!$G$4:$G$107,MATCH($A23,Partidos!$A$4:$A$107,0))),Puntuacion!$B$4,IF(($E23-$F23)=(INDEX(Partidos!$F$4:$F$107,MATCH($A23,Partidos!$A$4:$A$107,0))-INDEX(Partidos!$G$4:$G$107,MATCH($A23,Partidos!$A$4:$A$107,0))),Puntuacion!$B$5,IF(OR(AND($E23>$F23,INDEX(Partidos!$F$4:$F$107,MATCH($A23,Partidos!$A$4:$A$107,0))>INDEX(Partidos!$G$4:$G$107,MATCH($A23,Partidos!$A$4:$A$107,0))),AND($E23=$F23,INDEX(Partidos!$F$4:$F$107,MATCH($A23,Partidos!$A$4:$A$107,0))=INDEX(Partidos!$G$4:$G$107,MATCH($A23,Partidos!$A$4:$A$107,0))),AND($E23<$F23,INDEX(Partidos!$F$4:$F$107,MATCH($A23,Partidos!$A$4:$A$107,0))<INDEX(Partidos!$G$4:$G$107,MATCH($A23,Partidos!$A$4:$A$107,0)))),Puntuacion!$B$6,0))),IF(AND($E23=INDEX(Partidos!$F$4:$F$107,MATCH($A23,Partidos!$A$4:$A$107,0)),$F23=INDEX(Partidos!$G$4:$G$107,MATCH($A23,Partidos!$A$4:$A$107,0))),Puntuacion!$B$9,IF(($E23-$F23)=(INDEX(Partidos!$F$4:$F$107,MATCH($A23,Partidos!$A$4:$A$107,0))-INDEX(Partidos!$G$4:$G$107,MATCH($A23,Partidos!$A$4:$A$107,0))),Puntuacion!$B$10,IF(AND($H23<>"",$H23=INDEX(Partidos!$K$4:$K$107,MATCH($A23,Partidos!$A$4:$A$107,0))),Puntuacion!$B$11,0)))))),"") | H23: =IFERROR(INDEX(Simón!H$4:H$107,MATCH($A23,Simón!$A$4:$A$107,0)),"") | I23: =IFERROR(INDEX(Partidos!$J$4:$J$107,MATCH($A23,Partidos!$A$4:$A$107,0)),"") | J23: =IF(AND(INDEX(Partidos!$J$4:$J$107,MATCH($A23,Partidos!$A$4:$A$107,0))<>"Grupos",INDEX(Partidos!$H$4:$H$107,MATCH($A23,Partidos!$A$4:$A$107,0))="Finalizado",$H23<>"",$H23=INDEX(Partidos!$K$4:$K$107,MATCH($A23,Partidos!$A$4:$A$107,0))),1,0)
